Workbook

Sheet Фин.модель
B2: Выручка за год план | C2: =D9+F9+H9+J9+L9+N9+P9+R9+T9+V9+X9+Z9 -> 1.9495234e+08
B3: Чистая прибыль за год план | C3: =Z114 -> 53778632
B4: Рентабельность по чистой прибыли | C4: =C3/C2 -> 0.27585528
D5: план | E5: факт | F5: план | G5: факт | H5: план | I5: факт | J5: план | K5: факт | L5: план | M5: план | N5: план | O5: факт | P5: план | Q5: факт | R5: план | S5: факт | T5: план | U5: факт | V5: план | W5: факт | X5: план | Y5: факт | Z5: план | AA5: факт | AB5: итого план | AC5: итого факт | AD5: ср. за 12 мес.
B6: Периоды | D6: 1 | E6: 1 | F6: 2 | G6: 2 | H6: 3 | I6: 3 | J6: 4 | K6: 4 | L6: 5 | M6: 5 | N6: 6 | O6: 6 | P6: 7 | Q6: 7 | R6: 8 | S6: 8 | T6: 9 | U6: 9 | V6: 10 | W6: 10 | X6: 11 | Y6: 11 | Z6: 12 | AA6: 12
B7: Выручка всего, в т.ч. НДС | E7: =E9+E8 -> 10102615 | G7: =G8+G9 -> 12029194 | I7: =I8+I9 -> 11360493 | K7: =K8+K9 -> 12078469 | M7: =M9+M8 -> 12503715 | O7: =O8+O9 -> 10971089 | Q7: =Q8+Q9 -> 11716150 | S7: =S9+S8 -> 10843120 | U7: =U8+U9 -> 12070447 | W7: =W8+W9 -> 12434280 | Y7: =Y9+Y8 -> 12148776 | AA7: =AA8+AA9 -> 17199184 | AC7: =SUM(D7:AA7) -> 1.4545753e+08 | AD7: =AC7/12 -> 12121461
B8: НДС | E8: 468663.42 | G8: 536537.34 | I8: 563526.7 | K8: 536106.76 | M8: 545088.45 | O8: 495577.4 | Q8: 565315.09 | S8: 464282.96 | U8: 620657.12 | W8: 541266.87 | Y8: 551061.01 | AA8: 788270.54 | AC8: =SUM(D8:AA8) -> 6676353.7 | AD8: =AC8/12 -> 556362.8
B9: Выручка всего, без НДС | D9: =D38+D55+D56+D57 -> 12422914 | E9: =E38+E55+E56+E57 -> 9633951.5 | F9: =F38+F55+F56+F57 -> 12630400 | G9: =G38+G55+G56+G57 -> 11492657 | H9: =H38+H55+H56+H57 -> 16723253 | I9: =I38+I55+I56+I57 -> 10796966 | J9: =J38+J55+J56+J57 -> 15989617 | K9: =K38+K55+K56+K57 -> 11542362 | ... AA9: =AA38+AA55+AA56+AA57 -> 16410914 | AB9: =D9+F9+H9+J9+L9+N9+P9+R9+T9+V9+X9+Z9 -> 1.9495234e+08 | AC9: =E9+G9+I9+K9+M9+O9+Q9+S9+U9+W9+Y9+AA9 -> 1.3878118e+08 | AD9: =AC9/12 -> 11565098
B10: БЛОК ПРОДАЖ | C10: =D10+F10+H10+J10+L10+N10+P10+R10+T10+V10+X10+Z10 -> 754.93421 | D10: =D11+D16+D21 -> 38.70614 | E10: =E11+E16+E21 -> 12 | F10: =F11+F16+F21 -> 38.70614 | G10: =G11+G16+G21 -> 40 | H10: =H11+H16+H21 -> 38.70614 | I10: =I11+I16+I21 -> 44 | J10: =J11+J16+J21 -> 54.495614 | K10: =K11+K16+K21 -> 47 | ... AA10: =AA11+AA16+AA21 -> 21 | AB10: =C10 -> 754.93421 | AC10: =E10+G10+I10++K10+M10+O10+Q10+S10+U10+W10+Y10+AA10 -> 391.25
B11: total БОЛЬШИЕ | C11: =D11+F11+H11+J11+L11+N11+P11+R11+T11+V11+X11+Z11 -> 200 | D11: =D12+D13 -> 16.666667 | E11: =E12+E13 -> 5 | F11: =F12+F13 -> 16.666667 | G11: =G12+G13 -> 10 | H11: =H12+H13 -> 16.666667 | I11: =I12+I13 -> 13 | J11: =J12+J13 -> 16.666667 | K11: =K12+K13 -> 13 | ... AA11: =AA12+AA13 -> 8 | AB11: =C11 -> 200 | AC11: =E11+G11+I11++K11+M11+O11+Q11+S11+U11+W11+Y11+AA11 -> 131
B12: лиды с др. каналов | C12: =SUM(D12:Z12)-E12-G12-I12-K12-M12-O12-Q12-S12-U12-W12-Y12 -> 100 | D12: =D14*100/$C$14 -> 8.3333333 | E12: 4 | F12: =F14*100/$C$14 -> 8.3333333 | G12: 4 | H12: =H14*100/$C$14 -> 8.3333333 | I12: 4 | J12: =J14*100/$C$14 -> 8.3333333 | K12: 4 | L12: =L14*100/$C$14 -> 8.3333333 | M12: 3 | N12: =N14*100/$C$14 -> 8.3333333 | O12: 2 | P12: =P14*100/$C$14 -> 8.3333333 | Q12: 1 | R12: =R14*100/$C$14 -> 8.3333333 | S12: 4 | T12: =T14*100/$C$14 -> 8.3333333 | U12: 3 | V12: =V14*100/$C$14 -> 8.3333333 | W12: 4 | X12: =X14*100/$C$14 -> 8.3333333 | Y12: 5 | Z12: =Z14*100/$C$14 -> 8.3333333 | AA12: 1 | AB12: =C12 -> 100 | AC12: =E12+G12+I12++K12+M12+O12+Q12+S12+U12+W12+Y12+AA12 -> 39
B13: лиды маркетинг | C13: =SUM(D13:Z13)-E13-G13-I13-K13-M13-O13-Q13-S13-U13-W13-Y13 -> 100 | D13: =D15*100/$C$14 -> 8.3333333 | E13: 1 | F13: =F15*100/$C$14 -> 8.3333333 | G13: 6 | H13: =H15*100/$C$14 -> 8.3333333 | I13: 9 | J13: =J15*100/$C$14 -> 8.3333333 | K13: 9 | L13: =L15*100/$C$14 -> 8.3333333 | M13: 5 | N13: =N15*100/$C$14 -> 8.3333333 | O13: 15 | P13: =P15*100/$C$14 -> 8.3333333 | Q13: 16 | R13: =R15*100/$C$14 -> 8.3333333 | S13: 6 | T13: =T15*100/$C$14 -> 8.3333333 | U13: 5 | V13: =V15*100/$C$14 -> 8.3333333 | W13: 6 | X13: =X15*100/$C$14 -> 8.3333333 | Y13: 7 | Z13: =Z15*100/$C$14 -> 8.3333333 | AA13: 7 | AB13: =C13 -> 100 | AC13: =E13+G13+I13++K13+M13+O13+Q13+S13+U13+W13+Y13+AA13 -> 92
B14: продажи с др. каналов | C14: =SUM(D14:Z14)-E14-G14-I14-Q14-S14-U14-W14-Y14 -> 6 | D14: 0.5 | E14: 0 | F14: =D14 -> 0.5 | G14: =E14 -> 0 | H14: =F14 -> 0.5 | I14: 2 | J14: =H14 -> 0.5 | K14: 0 | L14: =J14 -> 0.5 | M14: =K14 -> 0 | N14: =L14 -> 0.5 | O14: =M14 -> 0 | P14: =N14 -> 0.5 | Q14: 1 | R14: =P14 -> 0.5 | S14: 1 | T14: =R14 -> 0.5 | U14: 0 | V14: =T14 -> 0.5 | W14: 1 | X14: =V14 -> 0.5 | Y14: 2 | Z14: =X14 -> 0.5 | AA14: 0 | AB14: =D14+F14+H14+J14+L14+N14+P14+R14+T14+V14+X14+Z14 -> 6 | AC14: =E14+G14+I14+K14+M14+O14+Q14+S14+U14+W14+Y14+AA14 -> 7
B15: продажи с маркетинга | D15: 0.5 | E15: 1 | F15: =D15 -> 0.5 | G15: 0 | H15: =F15 -> 0.5 | I15: 0 | J15: =H15 -> 0.5 | K15: 2 | L15: =J15 -> 0.5 | M15: 0 | N15: =L15 -> 0.5 | O15: =M15 -> 0 | P15: =N15 -> 0.5 | Q15: 3 | R15: =P15 -> 0.5 | S15: 0 | T15: =R15 -> 0.5 | U15: 1 | V15: =T15 -> 0.5 | W15: =U15 -> 1 | X15: =V15 -> 0.5 | Y15: 1 | Z15: =X15 -> 0.5 | AA15: 0 | AB15: =D15+F15+H15+J15+L15+N15+P15+R15+T15+V15+X15+Z15 -> 6 | AC15: =E15+G15+I15+K15+M15+O15+Q15+S15+U15+W15+Y15+AA15 -> 9
B16: total ТЕНДЕРЫ | C16: =C17+C18 -> 81.25 | D16: =D17+D18 -> 6.25 | E16: =E17+E18 -> 7 | F16: =F17+F18 -> 6.25 | G16: =G17+G18 -> 7 | H16: =H17+H18 -> 6.25 | I16: =I17+I18 -> 8 | J16: =J17+J18 -> 6.25 | ... AA16: =AA17+AA18 -> 3 | AB16: =D16+F16+H16+J16+L16+N16+P16+R16+T16+V16+X16+Z16 -> 81.25 | AC16: =E16+G16+I16+K16+M16+O16+Q16+S16+U16+W16+Y16+AA16 -> 53.25
B17: лиды с др. каналов | C17: =SUM(D17:Z17)-E17-G17-I17-K17-M17-O17-S17-U17-W17 -> 43.75 | D17: =D19*100/$C$19 -> 3.125 | E17: 6 | F17: =F19*100/$C$19 -> 3.125 | G17: 6 | H17: =H19*100/$C$19 -> 3.125 | I17: 4 | J17: =J19*100/$C$19 -> 3.125 | K17: 1 | L17: =L19*100/$C$19 -> 3.125 | M17: 5 | N17: =N19*100/$C$19 -> 3.125 | O17: 1 | P17: =P19*100/$C$19 -> 9.375 | Q17: 0 | R17: =R19*100/$C$19 -> 3.125 | S17: =S19*100/$C$19 -> 6.25 | T17: =T19*100/$C$19 -> 3.125 | U17: 2 | V17: =V19*100/$C$19 -> 3.125 | W17: 2 | X17: =X19*100/$C$19 -> 3.125 | Y17: =Y19*100/$C$19 -> 0 | Z17: =Z19*100/$C$19 -> 3.125 | AA17: 1 | AB17: =D17+F17+H17+J17+L17+N17+P17+R17+T17+V17+X17+Z17 -> 43.75 | AC17: =E17+G17+I17+K17+M17+O17+Q17+S17+U17+W17+Y17+AA17 -> 34.25
B18: лиды с маркетинга | C18: =SUM(D18:Z18)-E18-G18-I18-K18-M18-O18-Q18-U18 -> 37.5 | D18: =D20*100/$C$19 -> 3.125 | E18: 1 | F18: =F20*100/$C$19 -> 3.125 | G18: 1 | H18: =H20*100/$C$19 -> 3.125 | I18: 4 | J18: =J20*100/$C$19 -> 3.125 | K18: 3 | L18: =L20*100/$C$19 -> 3.125 | M18: 2 | N18: =N20*100/$C$19 -> 3.125 | O18: 2 | P18: =P20*100/$C$19 -> 3.125 | Q18: 2 | R18: =R20*100/$C$19 -> 3.125 | S18: =S20*100/$C$19 -> 0 | T18: =T20*100/$C$19 -> 3.125 | U18: 2 | V18: =V20*100/$C$19 -> 3.125 | W18: =W20*100/$C$19 -> 0 | X18: =X20*100/$C$19 -> 3.125 | Y18: =Y20*100/$C$19 -> 0 | Z18: =Z20*100/$C$19 -> 3.125 | AA18: 2 | AB18: =D18+F18+H18+J18+L18+N18+P18+R18+T18+V18+X18+Z18 -> 37.5 | AC18: =E18+G18+I18+K18+M18+O18+Q18+S18+U18+W18+Y18+AA18 -> 19
B19: продажи с др. каналов | C19: 16 | D19: 0.5 | E19: 0 | F19: =D19 -> 0.5 | G19: 1 | H19: =F19 -> 0.5 | I19: 0 | J19: =H19 -> 0.5 | K19: =I19 -> 0 | L19: =J19 -> 0.5 | M19: 1 | N19: =L19 -> 0.5 | O19: 0 | P19: =N19+1 -> 1.5 | Q19: 0 | R19: =N19 -> 0.5 | S19: 1 | T19: =R19 -> 0.5 | U19: 0 | V19: =T19 -> 0.5 | W19: =U19 -> 0 | X19: =V19 -> 0.5 | Y19: =W19 -> 0 | Z19: =X19 -> 0.5 | AA19: 1 | AB19: =D19+F19+H19+J19+L19+N19+P19+R19+T19+V19+X19+Z19 -> 7 | AC19: =E19+G19+I19+K19+M19+O19+Q19+S19+U19+W19+Y19+AA19 -> 4
B20: продажи с маркетинга | D20: 0.5 | E20: 0 | F20: =D20 -> 0.5 | G20: 0 | H20: =F20 -> 0.5 | I20: 0 | J20: =H20 -> 0.5 | K20: 1 | L20: =J20 -> 0.5 | M20: 0 | N20: =L20 -> 0.5 | O20: 1 | P20: =N20 -> 0.5 | Q20: 0 | R20: =P20 -> 0.5 | S20: =Q20 -> 0 | T20: =R20 -> 0.5 | U20: =S20 -> 0 | V20: =T20 -> 0.5 | W20: =U20 -> 0 | X20: =V20 -> 0.5 | Y20: =W20 -> 0 | ... AA20: =Y20 -> 0 | AB20: =D20+F20+H20+J20+L20+N20+P20+R20+T20+V20+X20+Z20 -> 6 | AC20: =E20+G20+I20+K20+M20+O20+Q20+S20+U20+W20+Y20+AA20 -> 2
B21: total МАЛЕНЬКИЕ | C21: =C22+C23 -> 473.68421 | D21: =D22+D23 -> 15.789474 | E21: =E22+E23 -> 0 | F21: =F22+F23 -> 15.789474 | G21: =G22+G23 -> 23 | H21: =H22+H23 -> 15.789474 | I21: =I22+I23 -> 23 | J21: =J22+J23 -> 31.578947 | ... AA21: =AA22+AA23 -> 10 | AB21: =D21+F21+H21+J21+L21+N21+P21+R21+T21+V21+X21+Z21 -> 473.68421 | AC21: =E21+G21+I21+K21+M21+O21+Q21+S21+U21+W21+Y21+AA21 -> 207
B22: лиды с др. каналов | C22: =SUM(D22:Z22)-E22-G22-I22-K22-M22-O22-Q22-S22-U22-W22-Y22 -> 236.84211 | D22: =D24*100/$C$24 -> 10.526316 | E22: 0 | F22: =F24*100/$C$24 -> 10.526316 | G22: 7 | H22: =H24*100/$C$24 -> 10.526316 | I22: 4 | J22: =J24*100/$C$24 -> 15.789474 | K22: 2 | L22: =L24*100/$C$24 -> 15.789474 | M22: 2 | N22: =N24*100/$C$24 -> 15.789474 | O22: 1 | P22: =P24*100/$C$24 -> 21.052632 | Q22: 1 | R22: =R24*100/$C$24 -> 21.052632 | S22: 2 | T22: =T24*100/$C$24 -> 21.052632 | U22: 2 | V22: =V24*100/$C$24 -> 31.578947 | W22: 0 | X22: =X24*100/$C$24 -> 31.578947 | Y22: 4 | Z22: =Z24*100/$C$24 -> 31.578947 | AA22: 2 | AB22: =D22+F22+H22+J22+L22+N22+P22+R22+T22+V22+X22+Z22 -> 236.84211 | AC22: =E22+G22+I22+K22+M22+O22+Q22+S22+U22+W22+Y22+AA22 -> 27
B23: лиды с маркетинга | C23: =SUM(D23:Z23)-E23-G23-I23-K23-M23-O23-Q23-S23-U23-W23-Y23 -> 236.84211 | D23: =D25*100/$C$25 -> 5.2631579 | E23: 0 | F23: =F25*100/$C$25 -> 5.2631579 | G23: 16 | H23: =H25*100/$C$25 -> 5.2631579 | I23: 19 | J23: =J25*100/$C$25 -> 15.789474 | K23: 28 | L23: =L25*100/$C$25 -> 15.789474 | M23: 19 | N23: =N25*100/$C$25 -> 15.789474 | O23: 20 | P23: =P25*100/$C$25 -> 26.315789 | Q23: 19 | R23: =R25*100/$C$25 -> 26.315789 | S23: 14 | T23: =T25*100/$C$25 -> 26.315789 | U23: 15 | V23: =V25*100/$C$25 -> 31.578947 | W23: 16 | X23: =X25*100/$C$25 -> 31.578947 | Y23: 6 | Z23: =Z25*100/$C$25 -> 31.578947 | AA23: 8 | AB23: =D23+F23+H23+J23+L23+N23+P23+R23+T23+V23+X23+Z23 -> 236.84211 | AC23: =E23+G23+I23+K23+M23+O23+Q23+S23+U23+W23+Y23+AA23 -> 180
B24: продажи с др. каналов | C24: 19 | D24: 2 | E24: 1 | F24: =D24 -> 2 | G24: 1 | H24: =F24 -> 2 | I24: 0 | J24: 3 | K24: 0 | L24: =J24 -> 3 | M24: 1 | N24: =L24 -> 3 | O24: 3 | P24: 4 | Q24: 1 | R24: 4 | S24: 0 | T24: 4 | U24: 0 | V24: 6 | W24: 0 | X24: 6 | Y24: 1 | Z24: 6 | AA24: 1 | AB24: =D24+F24+H24+J24+L24+N24+P24+R24+T24+V24+X24+Z24 -> 45 | AC24: =E24+G24+I24+K24+M24+O24+Q24+S24+U24+W24+Y24+AA24 -> 9
B25: продажи с маркетинга | C25: 19 | D25: 1 | E25: 0 | F25: =D25 -> 1 | G25: 1 | H25: =F25 -> 1 | I25: 2 | J25: 3 | K25: 1 | L25: =J25 -> 3 | M25: =K25 -> 1 | N25: =L25 -> 3 | O25: 4 | P25: 5 | Q25: 4 | R25: 5 | S25: 0 | T25: 5 | U25: 2 | V25: 6 | W25: 0 | X25: 6 | Y25: 0 | Z25: 6 | AA25: 0 | AB25: =D25+F25+H25+J25+L25+N25+P25+R25+T25+V25+X25+Z25 -> 45 | AC25: =E25+G25+I25+K25+M25+O25+Q25+S25+U25+W25+Y25+AA25 -> 15
AB26: =D26+F26+H26+J26+L26+N26+P26+R26+T26+V26+X26+Z26 -> 0 | AC26: =E26+G26+I26+K26+M26+O26+Q26+S26+U26+W26+Y26+AA26 -> 0
B27: план total ПРОДАЖИ | C27: =SUM(D27:Z27)-E27-G27-I27-K27-M27-O27-Q27-S27-U27-W27-Y27 -> 115 | D27: =SUM(D28:D30) -> 5 | E27: =SUM(E28:E30) -> 2 | F27: =SUM(F28:F30) -> 5 | G27: =SUM(G28:G30) -> 3 | H27: =SUM(H28:H30) -> 5 | I27: =SUM(I28:I30) -> 4 | J27: =SUM(J28:J30) -> 8 | K27: =SUM(K28:K30) -> 4 | ... AA27: =SUM(AA28:AA30) -> 2 | AB27: =D27+F27+H27+J27+L27+N27+P27+R27+T27+V27+X27+Z27 -> 115 | AC27: =E27+G27+I27+K27+M27+O27+Q27+S27+U27+W27+Y27+AA27 -> 47
B28: итого продажи большой целевой проект/мес | C28: =SUM(D28:Z28)-E28-G28-I28-K28-M28-Q28-S28-U28-W28-Y28 -> 12 | D28: 1 | E28: 1 | F28: 1 | G28: 0 | H28: 1 | I28: =I14+I15 -> 2 | J28: 1 | K28: =K14+K15 -> 2 | L28: 1 | M28: =M14+M15 -> 0 | N28: 1 | O28: 0 | P28: 1 | Q28: 4 | R28: 1 | S28: 1 | T28: 1 | U28: 1 | V28: 1 | W28: 2 | X28: 1 | Y28: 4 | Z28: 1 | AA28: =AA14+AA15 -> 0 | AB28: =D28+F28+H28+J28+L28+N28+P28+R28+T28+V28+X28+Z28 -> 12 | AC28: =E28+G28+I28+K28+M28+O28+Q28+S28+U28+W28+Y28+AA28 -> 17
B29: итого продажи тендер | C29: =SUM(D29:Z29)-E29--I29-K29-M29-O29-Q29-S29-U29-W29-Y29 -> 14 | D29: 1 | E29: 0 | F29: 1 | G29: 1 | H29: 1 | I29: =I19+I20 -> 0 | J29: 1 | K29: =K19+K20 -> 1 | L29: 1 | M29: =M19+M20 -> 1 | N29: 1 | O29: 1 | P29: 2 | Q29: 0 | R29: 1 | S29: 1 | T29: 1 | U29: 0 | V29: 1 | W29: 0 | X29: 1 | Y29: 0 | Z29: 1 | AA29: =AA19+AA20 -> 1 | AB29: =D29+F29+H29+J29+L29+N29+P29+R29+T29+V29+X29+Z29 -> 13 | AC29: =E29+G29+I29+K29+M29+O29+Q29+S29+U29+W29+Y29+AA29 -> 6
B30: итого продажи маленький | C30: =SUM(D30:Z30)-E30-G30-I30-K30-M30-O30-Q30-S30-U30-W30-Y30 -> 90 | D30: 3 | E30: 1 | F30: 3 | G30: 2 | H30: 3 | I30: =I24+I25 -> 2 | J30: 6 | K30: =K24+K25 -> 1 | L30: 6 | M30: =M24+M25 -> 2 | N30: 6 | O30: 7 | P30: 9 | Q30: 5 | R30: 9 | S30: 0 | T30: 9 | U30: 2 | V30: 12 | W30: 0 | X30: 12 | Y30: 1 | Z30: 12 | AA30: =AA24+AA25 -> 1 | AB30: =D30+F30+H30+J30+L30+N30+P30+R30+T30+V30+X30+Z30 -> 90 | AC30: =E30+G30+I30+K30+M30+O30+Q30+S30+U30+W30+Y30+AA30 -> 24
B31: Средний чек тендер, руб. | C31: ср.ч./мес 180 000+1 большой | AB31: =D31+F31+H31+J31+L31+N31+P31+R31+T31+V31+X31+Z31 -> 0 | AC31: =E31+G31+I31+K31+M31+O31+Q31+S31+U31+W31+Y31+AA31 -> 0 | AD31: средний чек
B32: Сумма продаж тендеры, руб. | G32: 3332650 | H32: =1800000+360000 -> 2160000 | I32: 0 | J32: =H32 -> 2160000 | K32: 13200000 | L32: =J32 -> 2160000 | M32: 4254624 | N32: =L32 -> 2160000 | O32: 2580000 | P32: =N32+12000000 -> 14160000 | Q32: 0 | R32: =N32 -> 2160000 | S32: 7200000 | T32: =R32 -> 2160000 | U32: 0 | V32: =T32 -> 2160000 | W32: =U32 -> 0 | X32: =V32 -> 2160000 | Y32: =W32 -> 0 | Z32: =X32 -> 2160000 | AA32: =Y32 -> 0 | AB32: =D32+F32+H32+J32+L32+N32+P32+R32+T32+V32+X32+Z32 -> 33600000 | AC32: =E32+G32+I32+K32+M32+O32+Q32+S32+U32+W32+Y32+AA32 -> 30567274 | AD32: =AC32/AC29 -> 5094545.7
B33: Сумма продаж большие целевые, руб. | D33: 680000 | E33: 687535 | F33: =D33 -> 680000 | G33: 0 | H33: =F33 -> 680000 | I33: =1475614+1181515 -> 2657129 | J33: =H33 -> 680000 | K33: =1483910+426559 -> 1910469 | L33: =J33 -> 680000 | M33: 0 | N33: =L33 -> 680000 | O33: =M33 -> 0 | P33: 782000 | Q33: 6936586 | R33: 782000 | S33: 3139164 | T33: 782000 | U33: 2268726 | V33: 899300 | W33: 6665737 | X33: 899300 | Y33: 4530921 | Z33: 899300 | AA33: 3000000 | AB33: =D33+F33+H33+J33+L33+N33+P33+R33+T33+V33+X33+Z33 -> 9123900 | AC33: =E33+G33+I33+K33+M33+O33+Q33+S33+U33+W33+Y33+AA33 -> 31796267 | AD33: =AC33/AC28 -> 1870368.6
B34: Сумма продаж маленькие total, руб. | D34: ='план поступлений'!B61 -> 195000 | E34: 23000 | F34: ='план поступлений'!C61 -> 195000 | G34: 53442 | H34: ='план поступлений'!D61 -> 195000 | I34: 40575 | J34: ='план поступлений'!E61 -> 390000 | K34: 231680 | L34: ='план поступлений'!F61 -> 390000 | M34: 700989 | N34: ='план поступлений'!G61 -> 390000 | O34: 810600 | P34: ='план поступлений'!H61 -> 585000 | Q34: 942352 | R34: ='план поступлений'!I61 -> 585000 | S34: 0 | T34: ='план поступлений'!J61 -> 585000 | U34: 408739 | V34: ='план поступлений'!K61 -> 780000 | W34: 0 | X34: ='план поступлений'!L61 -> 780000 | Y34: 352702 | Z34: ='план поступлений'!M61 -> 780000 | AA34: 131200 | AB34: =D34+F34+H34+J34+L34+N34+P34+R34+T34+V34+X34+Z34 -> 5850000 | AC34: =E34+G34+I34+K34+M34+O34+Q34+S34+U34+W34+Y34+AA34 -> 3695279 | AD34: =AC34/AC30 -> 153969.96
B35: ИТОГО ПРОДАЖ-ПЛАН total, руб. | C35: =D35+F35+H35+J35+L35+N35+P35+R35+T35+V35+X35+Z35 -> 48573900 | D35: =SUM(D32:D34) -> 875000 | E35: =SUM(E32:E34) -> 710535 | F35: =SUM(F32:F34) -> 875000 | G35: =SUM(G32:G34) -> 3386092 | H35: =SUM(H32:H34) -> 3035000 | I35: =SUM(I32:I34) -> 2697704 | J35: =SUM(J32:J34) -> 3230000 | K35: =SUM(K32:K34) -> 15342149 | ... AA35: =SUM(AA32:AA34) -> 3131200 | AB35: =D35+F35+H35+J35+L35+N35+P35+R35+T35+V35+X35+Z35 -> 48573900 | AC35: =E35+G35+I35+K35+M35+O35+Q35+S35+U35+W35+Y35+AA35 -> 66058820 | AD35: =AC35/AC27 -> 1405506.8
B36: БЛОК ПРИЗНАНИЯ ВЫРУЧКИ
B38: Выручка- текущий портфель | D38: =D48+D51+D53 -> 12372914 | E38: =E48+E51+E53 -> 9152436 | F38: =F48+F51+F53 -> 12385400 | G38: =G48+G51+G53 -> 10970653 | H38: =H48+H51+H53 -> 16478253 | I38: =I48+I51+I53 -> 10185626 | J38: =J48+J51+J53 -> 15744617 | K38: =K48+K51+K53 -> 10397909 | ... AA38: =AA48+AA51+AA53 -> 11625129
B39: EMS | D39: ='Выручка-план'!P188 -> 10564101 | E39: 0 | F39: =D39 -> 10564101 | G39: =E39 -> 0 | H39: =F39 -> 10564101 | I39: =G39 -> 0 | J39: =H39 -> 10564101 | K39: =I39 -> 0 | L39: =J39 -> 10564101 | M39: =K39 -> 0 | N39: =L39 -> 10564101 | P39: =N39 -> 10564101 | R39: =P39 -> 10564101 | S39: =Q39 -> 0 | T39: =R39 -> 10564101 | V39: =T39 -> 10564101 | X39: =V39 -> 10564101 | Z39: =X39 -> 10564101 | AA39: =Y39 -> 0
B40: Коэффициент сезонности | D40: ='коэффициент сезонности'!B14 -> 0.97168371 | E40: ='коэффициент сезонности'!C14 -> 0.97283127 | F40: ='коэффициент сезонности'!C14 -> 0.97283127 | H40: ='коэффициент сезонности'!D14 -> 1.051397 | J40: ='коэффициент сезонности'!E14 -> 1.0796754 | L40: ='коэффициент сезонности'!F14 -> 1.0130132 | N40: ='коэффициент сезонности'!G14 -> 0.9327982 | P40: ='коэффициент сезонности'!H14 -> 0.96752634 | R40: ='коэффициент сезонности'!I14 -> 0.99074117 | T40: ='коэффициент сезонности'!J14 -> 1.1088903 | V40: ='коэффициент сезонности'!K14 -> 1.1443706 | X40: ='коэффициент сезонности'!L14 -> 1.1698922 | Z40: ='коэффициент сезонности'!M5 -> 1.1943613 | AA40: ='коэффициент сезонности'!N5 -> 0
B41: EMS с учетом коэффициента сезонности | D41: =D39*D40 -> 10264965 | E41: ='БЛОК-ВЫРУЧКА'!G78 -> 8477722.7 | F41: =F39*F40 -> 10277088 | G41: ='БЛОК-ВЫРУЧКА'!L78 -> 8583947.3 | H41: =H39*H40 -> 11107064 | I41: ='БЛОК-ВЫРУЧКА'!O78 -> 8987414.3 | J41: =J39*J40 -> 11405800 | K41: ='БЛОК-ВЫРУЧКА'!Q78 -> 9814327.9 | L41: =L39*L40 -> 10701574 | M41: ='БЛОК-ВЫРУЧКА'!S78 -> 9934360.9 | N41: =N39*N40 -> 9854174.4 | O41: ='БЛОК-ВЫРУЧКА'!U78 -> 8150692.4 | P41: =P39*P40 -> 10221046 | Q41: ='БЛОК-ВЫРУЧКА'!W78 -> 8346684.2 | R41: =R39*R40 -> 10466290 | S41: ='БЛОК-ВЫРУЧКА'!Z78 -> 7048368.3 | T41: =T39*T40 -> 11714429 | U41: ='БЛОК-ВЫРУЧКА'!AC78 -> 7264562 | V41: =V39*V40 -> 12089246 | W41: ='БЛОК-ВЫРУЧКА'!AE78 -> 7420532.8 | X41: =X39*X40 -> 12358860 | Y41: ='БЛОК-ВЫРУЧКА'!AG78 -> 7546009.7 | Z41: =Z39*Z40 -> 12617353 | AA41: ='БЛОК-ВЫРУЧКА'!AI78 -> 9479767.7
B42: рост за счет роста среднего чека
...

Sheet Юнит ЕМС 
B1: Юр.лицо | C1: Клиент | D1: ЯНВАРЬ | G1: ФЕВРАЛЬ
B2: ТЕКУЩИЙ ПОРТФЕЛЬ ЕМС | C2: Проекты-текущий портфель EMS | D2: ФАКТ | E2: ПУЛ | F2: менеджер | G2: ФАКТ | H2: ПУЛ | I2: менеджер
A3: 1 | B3: 1-Й КРАСНОГВАРДЕЙСКИЙ ООО СЗ | C3: Сумма Элементов | D3: 20600 | G3: 27300 | H3: 5 | I3: Юмакулова Аида
A4: =A3+1 -> 2 | B4: ЮНИСЕНДЕР СМАРТ ООО | C4: RD Electronics | D4: 1452689 | G4: 332394.78 | H4: 5 | I4: Юмакулова Аида
A5: =A4+1 -> 3 | B5: А101 | D5: 51600 | G5: 51600 | H5: 5 | I5: Аблов Андрей
A6: =A5+1 -> 4 | B6: АО ЦВ ПРОТЕК | C6: Здравсити | D6: 10310 | G6: 98186 | H6: 1 | I6: Паршакина Ольга
A7: =A6+1 -> 5 | B7: АРТИС 21 ООО | C7: Artis21 | D7: 77047.619 | G7: 80900 | H7: 5 | I7: Боровова Дарья
A8: =A7+1 -> 6 | B8: БОРИСХОФ 1 ООО | C8: БорисХоф
A9: =A8+1 -> 7 | B9: БОРИСХОФ Т ООО
A10: =A9+1 -> 8 | B10: БОРИСХОФ ХОЛДИНГ ООО | C10: БорисХоф | D10: 63200 | G10: 46200 | H10: 1 | I10: Швецов Никита
A11: =A10+1 -> 9 | B11: БРОНИРОВАНИЕ ГОСТИНИЦ ООО | C11: Ostrovok | D11: 121050 | G11: 313450 | H11: 1 | I11: Радецкая Лика
A12: =A11+1 -> 10 | B12: БУРГЕР РУС ООО | C12: Бургеркинг | D12: 173500 | G12: 182600 | H12: 1 | I12: Радецкая Лика
A13: =A12+1 -> 11 | B13: ГК СБСВ-КЛЮЧАВТО ООО | C13: Keyauto | D13: 117642 | G13: 152208 | H13: 1 | I13: Паршакина Ольга
A14: =A13+1 -> 12 | B14: ДЖ.Т.И. РОССИЯ ООО | C14: JTI RMC | D14: 364902 | G14: 372524 | H14: 1 | I14: Еремин Михаил
A15: =A14+1 -> 13 | B15: ДИОНА ООО | C15: Внуково | D15: 166800 | G15: 147400 | H15: 1 | I15: Давтян Инга
A16: =A15+1 -> 14 | B16: ЕАПТЕКА ООО | C16: ЕАптека | H16: 1
A17: =A16+1 -> 15 | B17: ЕВРОПА ООО/ЭТНЕ ООО | C17: Vnukovo Outlet Village | D17: 244400 | G17: 244400 | H17: 1 | I17: Давтян Инга
A18: =A17+1 -> 16 | B18: ИМПУЛЬС ООО | C18: Amazing Red | D18: 327680 | G18: 314870.48 | H18: 5 | I18: Потковский Иван
A19: =A18+1 -> 17 | B19: ИНСТАМАРТ СЕРВИС ООО | C19: Сбермаркет ВнутриКом | D19: 211175 | G19: 236560 | H19: 5 | I19: Боровова Дарья
A20: =A18+1 -> 17 | B20: ИП Абдулин | C20: VK | D20: 11429 | H20: 5
A21: =A19+1 -> 18 | B21: ИП Суходоев | C21: Profmax | D21: 134400 | G21: 91200 | H21: 1 | I21: Радецкая Лика
A22: =A21+1 -> 19 | B22: КАЗАНЬ РЕАЛ ЭСТЕЙТ ООО | C22: Benetton | D22: 1033029.2 | G22: 891469.01 | H22: 1 | I22: Логвинова Уэзер
A23: =A22+1 -> 20 | B23: КАПИТАЛ ГРУП ООО | C23: Capital group | D23: 98150 | G23: 103057.5 | H23: 5 | I23: Потковский Иван
A24: =A23+1 -> 21 | B24: КАРШЕРИНГ РУССИЯ ПАО | C24: Делимобиль | D24: 72325 | G24: 126525 | H24: 5 | I24: Юмакулова Аида
A25: =A24+1 -> 22 | B25: КИНОПОИСК ООО | C25: Яндекс | D25: 203000 | G25: 248700 | H25: 5 | I25: Новикова Екатерина
A26: =A25+1 -> 23 | B26: КНАУФ ГИПС ООО | C26: Knauf | G26: 27360 | H26: 1 | I26: Гутина Юля
A27: =A26+1 -> 24 | B27: КОЛЕСА ДАРОМ.РУ ООО | C27: Колёса Даром | D27: 285714.29 | G27: 285714.29 | H27: 5 | I27: Новикова Екатерина
A28: =A27+1 -> 25 | B28: КОНДИТЕРСКАЯ ФАБРИКА ПОБЕДА ООО | C28: Победа Вкуса | D28: 114875 | G28: 114875 | H28: 1 | I28: Гутина Юля
A29: =A28+1 -> 26 | B29: КРАСНАЯ ПОЛЯНА НАО | C29: Красная поляна | D29: 82998.038 | G29: 234952.44 | H29: 1 | I29: Гутина Юля
A30: =A29+1 -> 27 | B30: Л'ОРЕАЛЬ АО | C30: CDMO | D30: 42565.333 | G30: 42565.333 | H30: 1 | I30: Андреева Валентина
A31: =A30+1 -> 28 | B31: Майндбокс ООО | C31: Mindbox | D31: 111254.67 | G31: 166070 | H31: 1 | I31: Гутина Юля
A32: =A31+1 -> 29 | B32: МАРС ООО | C32: Марс - комплексный проект, подписание доков, команда (Давтян, Ерёмин) | D32: 1006325
A33: =A32+1 -> 30 | C33: Экосистема | H33: 5 | I33: Соболевский Сергей
A34: =A33+1 -> 31 | B34: РУСКАН АО | C34: Royal Canin | G34: 571650 | H34: 1 | I34: Давтян Инга
A35: =A34+1 -> 32 | C35: Kinpet | G35: 563246.25 | H35: 1 | I35: Андреева Валентина
A36: =A35+1 -> 33 | C36: Любимчик | H36: 5 | I36: Потковский Иван
A37: =A36+1 -> 34 | B37: МЕТРО КЭШ ЭНД КЕРРИ ООО | C37: Metro | D37: 49982 | F37: Страхов Никита | H37: 5 | I37: Страхов Никита
A38: =A37+1 -> 35 | B38: МОСКВИЧ АО МАЗ | D38: 400000 | G38: 533000 | H38: 1 | I38: Швецов Никита
A39: =A38+1 -> 36 | B39: Мосурбанфорум
A40: =A39+1 -> 37 | B40: МУСА МОТОРС ДЖЕЙ ЭЛ ЭР ООО | C40: БорисХоф
...

Sheet БЛОК-ВЫРУЧКА
B1: Юр.лицо | C1: Клиент | E1: 6 мес | F1: 0.97 | I1: 0.97 | N1: 1.05 | P1: 1.08 | R1: 1.01 | T1: 0.93 | V1: 0.97 | Y1: 0.99 | AB1: 1.11 | AD1: 1.14 | AF1: 1.17 | AH1: 1.19
B2: ТЕКУЩИЙ ПОРТФЕЛЬ ЕМС | C2: Проекты-текущий портфель EMS | D2: ПУЛ | E2: план-среднемесячн. значение | F2: ПЛАН | G2: ФАКТ | I2: ПЛАН | J2: план в менеджерской таблице | L2: ФАКТ | M2: ПУЛ | N2: ПЛАН | O2: ФАКТ | P2: ПЛАН | Q2: ФАКТ | R2: ПЛАН | S2: ФАКТ | T2: ПЛАН | U2: ФАКТ | V2: ПЛАН | W2: ФАКТ | X2: ндс с выручки | Y2: ПЛАН | Z2: ФАКТ | AA2: ндс с выручки | AB2: ПЛАН | AC2: ФАКТ | AD2: ПЛАН | AE2: ФАКТ | AF2: ПЛАН | AG2: ФАКТ | AH2: ПЛАН | AI2: ФАКТ
F3: ЯНВАРЬ | I3: ФЕВРАЛЬ | N3: МАРТ | P3: АПРЕЛЬ | R3: МАЙ | T3: ИЮНЬ | V3: ИЮЛЬ | Y3: АВГУСТ | AB3: СЕНТЯБРЬ | AD3: ОКТЯБРЬ | AF3: НОЯБРЬ | AH3: ДЕКАБРЬ
A4: 1 | B4: 1-Й КРАСНОГВАРДЕЙСКИЙ ООО СЗ | C4: Сумма Элементов | E4: 42806.5 | F4: =E4*$F$1 -> 41522.305 | G4: =VLOOKUP(B4,[1]Лист_1!$A$1:$G$65536,7,0) -> 20600 | H4: =G4-F4 -> -20922.305 | I4: =E4*$I$1 -> 41522.305 | J4: 20600 | K4: =J4-I4 -> -20922.305 | L4: 27300 | N4: =E4*P1 -> 46231.02 | O4: 20600 | P4: =E4*$P$1 -> 46231.02 | Q4: 20600 | R4: =G4*$P$1 -> 22248 | S4: =VLOOKUP(B4,[2]Лист_1!$A$1:$C$65536,3,0) -> 20600 | T4: =I4*$T$1 -> 38615.744 | U4: 41200 | V4: =E4*$V$1 -> 41522.305 | W4: =VLOOKUP(B4,[3]Лист_1!$A$5:$F$55,4,0) -> 20600 | X4: =VLOOKUP(B4,[3]Лист_1!$A$5:$D$54,3,0) -> 1030 | Y4: =E4*$Y$1 -> 42378.435 | AB4: =E4*$AB$1 -> 47515.215 | AC4: 41200 | AD4: =E4*$AD$1 -> 48799.41 | AE4: =VLOOKUP(B4,[4]Лист_1!$A$5:$D$59,3,0) -> 20600 | AF4: =E4*$AF$1 -> 50083.605 | AG4: =VLOOKUP(B4,[5]Лист_1!$A$3:$C$50,3,0) -> 20600 | AH4: =G4*$AF$1 -> 24102 | AI4: =VLOOKUP(B4,[29]Лист_1!$A$5:$C$67,3,0) -> 20600
A5: =A4+1 -> 2 | B5: ЮНИСЕНДЕР СМАРТ ООО | C5: RD Electronics | D5: 5 | E5: 616827.86 | F5: =E5*$F$1 -> 598323.02 | G5: 1452689 | H5: =G5-F5 -> 854365.98 | I5: =E5*$I$1 -> 598323.02 | J5: 580000 | K5: =J5-I5 -> -18323.024 | L5: 332394.78 | N5: =E5*$N$1 -> 647669.25 | O5: 637722.33 | P5: =E5*$P$1 -> 666174.09 | Q5: 580627.81 | R5: =G5*$P$1 -> 1568904.1 | S5: =VLOOKUP(B5,[2]Лист_1!$A$1:$C$65536,3,0)+100000 -> 519672.94 | T5: =I5*$T$1 -> 556440.41 | U5: 365797.22 | V5: =E5*$V$1 -> 598323.02 | W5: =VLOOKUP(B5,[3]Лист_1!$A$5:$F$55,4,0) -> 515089.51 | X5: 25754.47 | Y5: =E5*$Y$1 -> 610659.58 | Z5: =VLOOKUP(B5,[6]Лист_1!$C$5:$E$64,3,0) -> 473226.97 | AB5: =E5*$AB$1 -> 684678.92 | AC5: 377158.32 | AD5: =E5*$AD$1 -> 703183.76 | AE5: =VLOOKUP(B5,[4]Лист_1!$A$5:$D$59,3,0) -> 715300.96 | AF5: =E5*$AF$1 -> 721688.6 | AG5: =VLOOKUP(B5,[5]Лист_1!$A$3:$C$50,3,0) -> 521234.77 | AH5: =G5*$AF$1 -> 1699646.1 | AI5: =VLOOKUP(B5,[29]Лист_1!$A$5:$C$67,3,0) -> 525939.36
A6: =A5+1 -> 3 | B6: А101 | D6: 5 | E6: 32390 | F6: =E6*$F$1 -> 31418.3 | G6: 51600 | H6: =G6-F6 -> 20181.7 | I6: =E6*$I$1 -> 31418.3 | J6: 130000 | K6: =J6-I6 -> 98581.7 | L6: 51600 | N6: =E6*$N$1 -> 34009.5 | P6: =E6*$P$1 -> 34981.2 | T6: =I6*$T$1 -> 29219.019 | V6: =E6*$V$1 -> 31418.3 | Y6: =E6*$Y$1 -> 32066.1 | Z6: 185800 | AB6: =E6*$AB$1 -> 35952.9 | AD6: =E6*$AD$1 -> 36924.6 | AE6: 51600 | AF6: =E6*$AF$1 -> 37896.3 | AG6: 38700 | AH6: =G6*$AF$1 -> 60372 | AI6: 51600
A7: =A6+1 -> 4 | B7: АО ЦВ ПРОТЕК | C7: Здравсити | D7: 1 | E7: 80764.833 | F7: =E7*$F$1 -> 78341.888 | G7: =VLOOKUP(B7,[1]Лист_1!$A$1:$G$65536,7,0) -> 10310 | H7: =G7-F7 -> -68031.888 | I7: =E7*$I$1 -> 78341.888 | J7: 30000 | K7: =J7-I7 -> -48341.888 | L7: 98186 | N7: =E7*$N$1 -> 84803.075 | O7: 192204 | P7: =E7*$P$1 -> 87226.02 | Q7: 218911 | R7: =G7*$P$1 -> 11134.8 | S7: =VLOOKUP(B7,[2]Лист_1!$A$1:$C$65536,3,0) -> 219047 | T7: =I7*$T$1 -> 72857.956 | U7: 142012 | V7: =E7*$V$1 -> 78341.888 | W7: =VLOOKUP(B7,[3]Лист_1!$A$5:$F$55,4,0) -> 220154 | X7: =VLOOKUP(B7,[3]Лист_1!$A$5:$D$54,3,0) -> 11007.7 | Y7: =E7*$Y$1 -> 79957.185 | Z7: =VLOOKUP(B7,[6]Лист_1!$C$5:$E$64,3,0) -> 18550 | AB7: =E7*$AB$1 -> 89648.965 | AD7: =E7*$AD$1 -> 92071.91
A8: =A7+1 -> 5 | B8: АРТИС 21 ООО | C8: Artis21 | D8: 5 | E8: 84041.667 | F8: =E8*$F$1 -> 81520.417 | G8: =VLOOKUP(B8,[1]Лист_1!$A$1:$G$65536,7,0) -> 77047.619 | H8: =G8-F8 -> -4472.7976 | I8: =E8*$I$1 -> 81520.417 | J8: 69400 | K8: =J8-I8 -> -12120.417 | L8: 80900 | N8: =E8*$N$1 -> 88243.75 | O8: 67950 | P8: =E8*$P$1 -> 90765 | Q8: 110350 | R8: =G8*$P$1 -> 83211.429 | S8: =VLOOKUP(B8,[2]Лист_1!$A$1:$C$65536,3,0) -> 110350 | T8: =I8*$T$1 -> 75813.988 | Z8: =VLOOKUP(B8,[6]Лист_1!$C$5:$E$64,3,0)+69400 -> 138800 | AB8: =E8*$AB$1 -> 93286.25 | AC8: =VLOOKUP(B8,[7]Лист_1!$A$3:$E$57,4,0) -> 69400 | AD8: =E8*$AD$1 -> 95807.5 | AE8: =VLOOKUP(B8,[4]Лист_1!$A$5:$D$59,3,0) -> 95300 | AF8: =E8*$AF$1 -> 98328.75 | AG8: =VLOOKUP(B8,[5]Лист_1!$A$3:$C$50,3,0) -> 39950 | AH8: =G8*$AF$1 -> 90145.714 | AI8: =VLOOKUP(B8,[29]Лист_1!$A$5:$C$67,3,0) -> 109350
A9: =A8+1 -> 6 | B9: БОРИСХОФ 1 ООО | C9: БорисХоф | E9: 15883.333 | F9: =E9*$F$1 -> 15406.833 | H9: =G9-F9 -> -15406.833 | I9: =E9*$I$1 -> 15406.833 | K9: =J9-I9 -> -15406.833 | N9: =E9*$N$1 -> 16677.5
A10: =A9+1 -> 7 | B10: БОРИСХОФ Т ООО | E10: 1500 | F10: =E10*$F$1 -> 1455 | H10: =G10-F10 -> -1455 | I10: =E10*$I$1 -> 1455 | K10: =J10-I10 -> -1455 | N10: =E10*$N$1 -> 1575
A11: =A10+1 -> 8 | B11: БОРИСХОФ ХОЛДИНГ ООО | C11: БорисХоф | D11: 1 | E11: 111396.67 | F11: =E11*$F$1 -> 108054.77 | G11: =VLOOKUP(B11,[1]Лист_1!$A$1:$G$65536,7,0) -> 63200 | H11: =G11-F11 -> -44854.767 | I11: =E11*$I$1 -> 108054.77 | J11: 50000 | K11: =J11-I11 -> -58054.767 | L11: 46200 | N11: =E11*$N$1 -> 116966.5 | O11: 53900 | P11: =E11*$P$1 -> 120308.4 | Q11: 41000 | R11: =G11*$P$1 -> 68256 | S11: =VLOOKUP(B11,[2]Лист_1!$A$1:$C$65536,3,0) -> 38000 | T11: =I11*$T$1 -> 100490.93 | U11: 88620 | V11: =E11*$V$1 -> 108054.77 | W11: =VLOOKUP(B11,[3]Лист_1!$A$5:$F$55,4,0) -> 114180 | X11: =VLOOKUP(B11,[3]Лист_1!$A$5:$D$54,3,0) -> 5709 | Y11: =E11*$Y$1 -> 110282.7 | Z11: 145728.57 | AB11: =E11*$AB$1 -> 123650.3 | AC11: =VLOOKUP(B11,[7]Лист_1!$A$3:$E$57,4,0) -> 119880 | AD11: =E11*$AD$1 -> 126992.2 | AE11: =VLOOKUP(B11,[4]Лист_1!$A$5:$D$59,3,0) -> 133400 | AF11: =E11*$AF$1 -> 130334.1 | AG11: =VLOOKUP(B11,[5]Лист_1!$A$3:$C$50,3,0) -> 104160 | AH11: =G11*$AF$1 -> 73944 | AI11: =VLOOKUP(B11,[29]Лист_1!$A$5:$C$67,3,0) -> 109696
A12: =A11+1 -> 9 | B12: БРОНИРОВАНИЕ ГОСТИНИЦ ООО | C12: Ostrovok | D12: 3 | E12: 352588.33 | F12: =E12*$F$1 -> 342010.68 | G12: =VLOOKUP(B12,[1]Лист_1!$A$1:$G$65536,7,0) -> 121050 | H12: =G12-F12 -> -220960.68 | I12: =E12*$I$1 -> 342010.68 | J12: 300000 | K12: =J12-I12 -> -42010.683 | L12: 313450 | N12: =E12*$N$1 -> 370217.75 | O12: 247650 | P12: =E12*$P$1 -> 380795.4 | Q12: 322870 | R12: =G12*$P$1 -> 130734 | S12: =VLOOKUP(B12,[2]Лист_1!$A$1:$C$65536,3,0) -> 254960 | T12: =I12*$T$1 -> 318069.94 | U12: 195900 | V12: =E12*$V$1 -> 342010.68 | W12: =VLOOKUP(B12,[3]Лист_1!$A$5:$F$55,4,0) -> 274070 | X12: =VLOOKUP(B12,[3]Лист_1!$A$5:$D$54,3,0) -> 13703.5 | Y12: =E12*$Y$1 -> 349062.45 | Z12: =VLOOKUP(B12,[6]Лист_1!$C$5:$E$64,3,0) -> 107560 | AB12: =E12*$AB$1 -> 391373.05 | AC12: =VLOOKUP(B12,[7]Лист_1!$A$3:$E$57,4,0) -> 77350 | AE12: =VLOOKUP(B12,[4]Лист_1!$A$5:$D$59,3,0) -> 25050 | AG12: =VLOOKUP(B12,[5]Лист_1!$A$3:$C$50,3,0) -> 21150 | AI12: =VLOOKUP(B12,[29]Лист_1!$A$5:$C$67,3,0) -> 17180
A13: =A12+1 -> 10 | B13: БУРГЕР РУС ООО | C13: Бургеркинг | D13: 3 | E13: 94200 | F13: =E13*$F$1 -> 91374 | G13: =VLOOKUP(B13,[1]Лист_1!$A$1:$G$65536,7,0) -> 173500 | H13: =G13-F13 -> 82126 | I13: =E13*$I$1 -> 91374 | J13: 200000 | K13: =J13-I13 -> 108626 | L13: 182600 | N13: =E13*$N$1 -> 98910 | O13: 181400 | P13: =E13*$P$1 -> 101736 | Q13: 176200 | R13: =G13*$P$1 -> 187380 | S13: =VLOOKUP(B13,[2]Лист_1!$A$1:$C$65536,3,0) -> 180500 | T13: =I13*$T$1 -> 84977.82 | U13: 234000 | V13: =E13*$V$1 -> 91374 | W13: =VLOOKUP(B13,[3]Лист_1!$A$5:$F$55,4,0) -> 235000 | X13: =VLOOKUP(B13,[3]Лист_1!$A$5:$D$54,3,0) -> 11750 | Y13: =E13*$Y$1 -> 93258 | Z13: =VLOOKUP(B13,[6]Лист_1!$C$5:$E$64,3,0) -> 237000 | AB13: =E13*$AB$1 -> 104562 | AC13: =VLOOKUP(B13,[7]Лист_1!$A$3:$E$57,4,0) -> 236500 | AD13: =E13*$AD$1 -> 107388 | AE13: =VLOOKUP(B13,[4]Лист_1!$A$5:$D$59,3,0) -> 237600 | AF13: =E13*$AF$1 -> 110214 | AG13: =VLOOKUP(B13,[5]Лист_1!$A$3:$C$50,3,0) -> 233600 | AH13: =G13*$AF$1 -> 202995 | AI13: =VLOOKUP(B13,[29]Лист_1!$A$5:$C$67,3,0) -> 236000
A14: =A13+1 -> 11 | B14: ГК СБСВ-КЛЮЧАВТО ООО | C14: Keyauto | D14: 1 | E14: 153622 | F14: =E14*$F$1 -> 149013.34 | G14: =VLOOKUP(B14,[1]Лист_1!$A$1:$G$65536,7,0) -> 117642 | H14: =G14-F14 -> -31371.34 | I14: =E14*$I$1 -> 149013.34 | J14: 140000 | K14: =J14-I14 -> -9013.34 | L14: 152208 | N14: =E14*$N$1 -> 161303.1 | O14: 160902 | P14: =E14*$P$1 -> 165911.76 | Q14: 177658.9 | R14: =G14*$P$1 -> 127053.36 | T14: =I14*$T$1 -> 138582.41
A15: =A14+1 -> 12 | B15: ДЖ.Т.И. РОССИЯ ООО | C15: JTI RMC | D15: 1 | E15: 515262.41 | F15: =E15*$F$1 -> 499804.54 | G15: =VLOOKUP(B15,[1]Лист_1!$A$1:$G$65536,7,0) -> 364902 | H15: =G15-F15 -> -134902.54 | I15: =E15*$I$1 -> 499804.54 | J15: 350000 | K15: =J15-I15 -> -149804.54 | L15: 372524 | N15: =E15*$N$1 -> 541025.53 | O15: 380710 | P15: =E15*$P$1 -> 556483.4 | Q15: 368220 | R15: =G15*$P$1 -> 394094.16 | S15: =VLOOKUP(B15,[2]Лист_1!$A$1:$C$65536,3,0) -> 465308 | T15: =I15*$T$1 -> 464818.22 | U15: 340228 | V15: =E15*$V$1 -> 499804.54 | W15: =VLOOKUP(B15,[3]Лист_1!$A$5:$F$55,4,0) -> 305628 | X15: =VLOOKUP(B15,[3]Лист_1!$A$5:$D$54,3,0) -> 15281.4 | Y15: =E15*$Y$1 -> 510109.79 | Z15: =VLOOKUP(B15,[6]Лист_1!$C$5:$E$64,3,0) -> 500742 | AB15: =E15*$AB$1 -> 571941.28 | AC15: =VLOOKUP(B15,[7]Лист_1!$A$3:$E$57,4,0) -> 509163.9 | AD15: =E15*$AD$1 -> 587399.15 | AE15: =VLOOKUP(B15,[4]Лист_1!$A$5:$D$59,3,0) -> 442967.7 | AF15: =E15*$AF$1 -> 602857.02 | AG15: =VLOOKUP(B15,[5]Лист_1!$A$3:$C$50,3,0) -> 431505.1 | AH15: =G15*$AF$1 -> 426935.34 | AI15: =VLOOKUP(B15,[29]Лист_1!$A$5:$C$67,3,0) -> 412654.4
A16: =A15+1 -> 13 | B16: ДИОНА ООО | C16: Внуково | D16: 3 | E16: 114358.33 | F16: =E16*$F$1 -> 110927.58 | G16: =VLOOKUP(B16,[1]Лист_1!$A$1:$G$65536,7,0) -> 166800 | H16: =G16-F16 -> 55872.417 | I16: =E16*$I$1 -> 110927.58 | J16: 100000 | K16: =J16-I16 -> -10927.583 | L16: 391800 | N16: =E16*$N$1 -> 120076.25 | O16: 301200 | Y16: =E16*$Y$1 -> 113214.75
A17: =A16+1 -> 14 | B17: ЕАПТЕКА ООО | C17: ЕАптека | E17: 27700.667 | F17: =E17*$F$1 -> 26869.647 | H17: =G17-F17 -> -26869.647 | I17: =E17*$I$1 -> 26869.647 | J17: 0 | K17: =J17-I17 -> -26869.647 | N17: =E17*$N$1 -> 29085.7 | Y17: =E17*$Y$1 -> 27423.66
A18: =A17+1 -> 15 | B18: ЕВРОПА ООО | C18: Vnukovo Outlet Village | E18: 179283.33 | F18: =E18*$F$1 -> 173904.83 | G18: =VLOOKUP(B18,[1]Лист_1!$A$1:$G$65536,7,0) -> 186200 | H18: =G18-F18 -> 12295.167 | I18: =E18*$I$1 -> 173904.83 | J18: 0 | K18: =J18-I18 -> -173904.83 | N18: =E18*$N$1 -> 188247.5 | Y18: =E18*$Y$1 -> 177490.5
A19: =A18+1 -> 16 | B19: ЭТНЕ ООО | C19: Vnukovo Outlet Village | D19: 3 | G19: =VLOOKUP(B19,[1]Лист_1!$A$1:$G$65536,7,0) -> 58200 | H19: =G19-F19 -> 58200 | I19: 173905 | J19: 200000 | K19: =J19-I19 -> 26095 | Y19: =E19*$Y$1 -> 0
A20: =A19+1 -> 17 | B20: ИМПУЛЬС ООО | C20: Amazing Red | D20: 3 | E20: 313758.33 | F20: =E20*$F$1 -> 304345.58 | G20: =VLOOKUP(B20,[1]Лист_1!$A$1:$G$65536,7,0) -> 327680 | H20: =G20-F20 -> 23334.417 | I20: =E20*$I$1 -> 304345.58 | J20: 220000 | K20: =J20-I20 -> -84345.583 | L20: 314870.48 | N20: =E20*$N$1 -> 329446.25 | O20: 299000 | P20: =E20*$P$1 -> 338859 | Q20: 504590 | R20: =G20*$P$1 -> 353894.4 | S20: =VLOOKUP(B20,[2]Лист_1!$A$1:$C$65536,3,0) -> 296860 | T20: =I20*$T$1 -> 283041.39 | U20: 262220 | V20: =E20*$V$1 -> 304345.58 | W20: =VLOOKUP(B20,[3]Лист_1!$A$5:$F$55,4,0) -> 231980 | X20: =VLOOKUP(B20,[3]Лист_1!$A$5:$D$54,3,0) -> 11599 | Y20: =E20*$Y$1 -> 310620.75 | Z20: =VLOOKUP(B20,[6]Лист_1!$C$5:$E$64,3,0) -> 51200 | AE20: =VLOOKUP(B20,[4]Лист_1!$A$5:$D$59,3,0) -> 57200
A21: =A20+1 -> 18 | B21: ИНСТАМАРТ СЕРВИС ООО | C21: Сбермаркет ВнутриКом | D21: 3 | E21: 542963.33 | F21: =E21*$F$1 -> 526674.43 | G21: =VLOOKUP(B21,[1]Лист_1!$A$1:$G$65536,7,0) -> 211175 | H21: =G21-F21 -> -315499.43 | I21: =E21*$I$1 -> 526674.43 | J21: 200000 | K21: =J21-I21 -> -326674.43 | L21: 236560 | N21: =E21*$N$1 -> 570111.5 | O21: 139340 | P21: =E21*$P$1 -> 586400.4 | Q21: 118020 | R21: =G21*$P$1 -> 228069 | S21: =VLOOKUP(B21,[2]Лист_1!$A$1:$C$65536,3,0) -> 20800 | T21: =I21*$T$1 -> 489807.22 | U21: 86510 | V21: =E21*$V$1 -> 526674.43 | Z21: 75400
A22: =A21+1 -> 19 | B22: ИП Абдулин | C22: VK | G22: 11429 | H22: =G22-F22 -> 11429 | I22: =E22*$I$1 -> 0 | K22: =J22-I22 -> 0 | T22: =I22*$T$1 -> 0 | Y22: =E22*$Y$1 -> 0
A23: =A22+1 -> 20 | B23: ДЗЕН.ПЛАТФОРМА ООО | C23: VK | O23: 12274 | Q23: 12274 | S23: =VLOOKUP(B23,[2]Лист_1!$A$1:$C$65536,3,0) -> 6137 | T23: =I23*$T$1 -> 0 | U23: 33683 | W23: =VLOOKUP(B23,[3]Лист_1!$A$5:$F$55,4,0) -> 12274 | X23: =VLOOKUP(B23,[3]Лист_1!$A$5:$D$54,3,0) -> 613.7 | Y23: =E23*$Y$1 -> 0 | Z23: =VLOOKUP(B23,[6]Лист_1!$C$5:$E$64,3,0) -> 5900 | AC23: =VLOOKUP(B23,[7]Лист_1!$A$3:$E$57,4,0) -> 24264 | AD23: =E23*$AD$1 -> 0 | AE23: =VLOOKUP(B23,[4]Лист_1!$A$5:$D$59,3,0) -> 15082
A24: =A23+1 -> 21 | B24: ВК ООО | C24: VK | AI24: =VLOOKUP(B24,[29]Лист_1!$A$5:$C$67,3,0) -> 12274
A25: =A23+1 -> 21 | B25: ДОНОР-СЁРЧ (ПОИСК ДОНОРОВ) АНО | C25: DonorSearch | O25: 76190.476 | Q25: 38095.238 | S25: =VLOOKUP(B25,[2]Лист_1!$A$1:$C$65536,3,0) -> 38095.238 | T25: =I25*$T$1 -> 0 | U25: 38095.238 | W25: =VLOOKUP(B25,[3]Лист_1!$A$5:$F$55,4,0) -> 38095.238 | X25: =VLOOKUP(B25,[3]Лист_1!$A$5:$D$54,3,0) -> 1904.7619 | Y25: =E25*$Y$1 -> 0 | Z25: =VLOOKUP(B25,[6]Лист_1!$C$5:$E$64,3,0) -> 38095.238 | AC25: =VLOOKUP(B25,[7]Лист_1!$A$3:$E$57,4,0) -> 38095.238 | AD25: =E25*$AD$1 -> 0 | AE25: =VLOOKUP(B25,[4]Лист_1!$A$5:$D$59,3,0) -> 38095.238 | AG25: =VLOOKUP(B25,[5]Лист_1!$A$3:$C$50,3,0) -> 38095.238 | AI25: =VLOOKUP(B25,[29]Лист_1!$A$5:$C$67,3,0) -> 38095.238
A26: =A23+1 -> 21 | B26: ИП Суходоев | C26: Profmax | D26: 3 | E26: 186900 | F26: =E26*$F$1 -> 181293 | G26: 134400 | H26: =G26-F26 -> -46893 | I26: =E26*$I$1 -> 181293 | J26: 110000 | K26: =J26-I26 -> -71293 | L26: 91200 | N26: =E26*$N$1 -> 196245 | O26: 82400 | P26: =E26*$P$1 -> 201852 | Q26: 109600 | R26: =G26*$P$1 -> 145152
A27: =A26+1 -> 22 | B27: КАЗАНЬ РЕАЛ ЭСТЕЙТ ООО | C27: Benetton | D27: 1 | E27: 703840.2 | F27: =E27*$F$1 -> 682724.99 | G27: =VLOOKUP(B27,[1]Лист_1!$A$1:$G$65536,7,0) -> 1033029.2 | H27: =G27-F27 -> 350304.18 | I27: =E27*$I$1 -> 682724.99 | J27: 800000 | K27: =J27-I27 -> 117275.01 | L27: 891469.01 | N27: =E27*$N$1 -> 739032.21 | O27: 723546 | P27: =E27*$P$1 -> 760147.42 | Q27: 905207.01 | R27: =G27*$P$1 -> 1115671.5 | S27: =VLOOKUP(B27,[2]Лист_1!$A$1:$C$65536,3,0) -> 817175.02 | T27: =I27*$T$1 -> 634934.24 | U27: 861405.01 | V27: =E27*$V$1 -> 682724.99 | W27: =VLOOKUP(B27,[3]Лист_1!$A$5:$F$55,4,0) -> 1010565 | X27: 50528.26 | Y27: =E27*$Y$1 -> 696801.8 | Z27: 852152.51 | AB27: =E27*$AB$1 -> 781262.62 | AC27: =VLOOKUP(B27,[7]Лист_1!$A$3:$E$57,4,0) -> 950575.01 | AD27: =E27*$AD$1 -> 802377.83 | AE27: =VLOOKUP(B27,[4]Лист_1!$A$5:$D$59,3,0) -> 782920.01 | AF27: =E27*$AF$1 -> 823493.03 | AG27: =VLOOKUP(B27,[5]Лист_1!$A$3:$C$50,3,0) -> 839710.01 | AH27: =G27*$AF$1 -> 1208644.1 | AI27: =VLOOKUP(B27,[29]Лист_1!$A$5:$C$67,3,0) -> 790700
A28: =A27+1 -> 23 | B28: КАПИТАЛ ГРУП ООО | C28: Capital group | D28: 3 | E28: 134250 | F28: =E28*$F$1 -> 130222.5 | G28: =VLOOKUP(B28,[1]Лист_1!$A$1:$G$65536,7,0) -> 98150 | H28: =G28-F28 -> -32072.5 | I28: =E28*$I$1 -> 130222.5 | J28: 90000 | K28: =J28-I28 -> -40222.5 | L28: 103057.5 | N28: =E28*$N$1 -> 140962.5 | O28: 117200 | P28: =E28*$P$1 -> 144990 | Q28: 192750 | R28: =G28*$P$1 -> 106002 | S28: =VLOOKUP(B28,[2]Лист_1!$A$1:$C$65536,3,0) -> 117200 | T28: =I28*$T$1 -> 121106.93 | U28: 69900 | V28: =E28*$V$1 -> 130222.5 | W28: =VLOOKUP(B28,[3]Лист_1!$A$5:$F$55,4,0) -> 145450 | X28: =VLOOKUP(B28,[3]Лист_1!$A$5:$D$54,3,0) -> 7272.5 | Y28: =E28*$Y$1 -> 132907.5 | Z28: =VLOOKUP(B28,[6]Лист_1!$C$5:$E$64,3,0) -> 188150 | AB28: =E28*$AB$1 -> 149017.5 | AC28: =VLOOKUP(B28,[7]Лист_1!$A$3:$E$57,4,0) -> 93550 | AD28: =E28*$AD$1 -> 153045 | AE28: =VLOOKUP(B28,[4]Лист_1!$A$5:$D$59,3,0) -> 158848 | AF28: =E28*$AF$1 -> 157072.5 | AG28: =VLOOKUP(B28,[5]Лист_1!$A$3:$C$50,3,0) -> 93550 | AH28: =G28*$AF$1 -> 114835.5 | AI28: =VLOOKUP(B28,[29]Лист_1!$A$5:$C$67,3,0) -> 319272
A29: =A28+1 -> 24 | B29: КАРШЕРИНГ РУССИЯ ПАО | C29: Делимобиль | D29: 5 | E29: 143845.83 | F29: =E29*$F$1 -> 139530.46 | G29: =VLOOKUP(B29,[1]Лист_1!$A$1:$G$65536,7,0) -> 72325 | H29: =G29-F29 -> -67205.458 | I29: =E29*$I$1 -> 139530.46 | J29: 120000 | K29: =J29-I29 -> -19530.458 | L29: 126525 | N29: =E29*$N$1 -> 151038.13 | O29: 90150 | P29: =E29*$P$1 -> 155353.5 | Q29: 94900 | R29: =G29*$P$1 -> 78111 | S29: =VLOOKUP(B29,[2]Лист_1!$A$1:$C$65536,3,0) -> 53950 | T29: =I29*$T$1 -> 129763.33 | U29: 56500 | V29: =E29*$V$1 -> 139530.46 | W29: =VLOOKUP(B29,[3]Лист_1!$A$5:$F$55,4,0) -> 126375 | X29: =VLOOKUP(B29,[3]Лист_1!$A$5:$D$54,3,0) -> 6318.75 | Y29: =E29*$Y$1 -> 142407.38 | Z29: =VLOOKUP(B29,[6]Лист_1!$C$5:$E$64,3,0) -> 127600 | AB29: =E29*$AB$1 -> 159668.88 | AC29: =VLOOKUP(B29,[7]Лист_1!$A$3:$E$57,4,0) -> 194400 | AD29: =E29*$AD$1 -> 163984.25 | AE29: =VLOOKUP(B29,[4]Лист_1!$A$5:$D$59,3,0) -> 148500 | AF29: =E29*$AF$1 -> 168299.62 | AG29: =VLOOKUP(B29,[5]Лист_1!$A$3:$C$50,3,0) -> 135900 | AH29: =G29*$AF$1 -> 84620.25 | AI29: =VLOOKUP(B29,[29]Лист_1!$A$5:$C$67,3,0) -> 75600
A30: =A29+1 -> 25 | B30: КИНОПОИСК ООО | C30: Яндекс | D30: 5 | E30: 311316.67 | F30: =E30*$F$1 -> 301977.17 | G30: =VLOOKUP(B30,[1]Лист_1!$A$1:$G$65536,7,0) -> 203000 | H30: =G30-F30 -> -98977.167 | I30: =E30*$I$1 -> 301977.17 | J30: 200000 | K30: =J30-I30 -> -101977.17 | L30: 248700 | N30: =E30*$N$1 -> 326882.5 | O30: 206300 | P30: =E30*$P$1 -> 336222 | Q30: 348200 | R30: =G30*$P$1 -> 219240 | S30: =VLOOKUP(B30,[2]Лист_1!$A$1:$C$65536,3,0) -> 312500 | T30: =I30*$T$1 -> 280838.77 | U30: 349300 | V30: =E30*$V$1 -> 301977.17 | W30: =VLOOKUP(B30,[3]Лист_1!$A$5:$F$55,4,0) -> 600600.8 | X30: =VLOOKUP(B30,[3]Лист_1!$A$5:$D$54,3,0) -> 30030.04 | Y30: =E30*$Y$1 -> 308203.5 | Z30: 371900 | AB30: =E30*$AB$1 -> 345561.5 | AC30: =VLOOKUP(B30,[7]Лист_1!$A$3:$E$57,4,0) -> 396400 | AD30: =E30*$AD$1 -> 354901 | AE30: 243904.76 | AF30: =E30*$AF$1 -> 364240.5 | AG30: 244700 | AH30: =G30*$AF$1 -> 237510 | AI30: =VLOOKUP(B30,[29]Лист_1!$A$5:$C$67,3,0) -> 169350
A31: =A30+1 -> 26 | B31: КНАУФ ГИПС ООО | C31: Knauf | E31: 26669.167 | F31: =E31*$F$1 -> 25869.092 | H31: =G31-F31 -> -25869.092 | I31: =E31*$I$1 -> 25869.092 | K31: =J31-I31 -> -25869.092 | L31: 27360 | N31: =E31*$N$1 -> 28002.625 | O31: 15620 | P31: =E31*$P$1 -> 28802.7 | R31: =G31*$P$1 -> 0 | V31: =E31*$V$1 -> 25869.092 | W31: =VLOOKUP(B31,[3]Лист_1!$A$5:$F$55,4,0) -> 53210 | X31: =VLOOKUP(B31,[3]Лист_1!$A$5:$D$54,3,0) -> 2660.5 | Y31: =E31*$Y$1 -> 26402.475 | Z31: 37680 | AB31: =E31*$AB$1 -> 29602.775 | AC31: 89290 | AD31: =E31*$AD$1 -> 30402.85 | AE31: =VLOOKUP(B31,[4]Лист_1!$A$5:$D$59,3,0) -> 100435 | AF31: =E31*$AF$1 -> 31202.925 | AG31: =VLOOKUP(B31,[5]Лист_1!$A$3:$C$50,3,0) -> 76789 | AH31: =G31*$AF$1 -> 0 | AI31: =VLOOKUP(B31,[29]Лист_1!$A$5:$C$67,3,0) -> 17746
A32: =A31+1 -> 27 | B32: КОЛЕСА ДАРОМ.РУ ООО | C32: Колёса Даром | E32: 300000 | F32: =E32*$F$1 -> 291000 | G32: =VLOOKUP(B32,[1]Лист_1!$A$1:$G$65536,7,0) -> 285714.29 | H32: =G32-F32 -> -5285.7143 | I32: =E32*$I$1 -> 291000 | J32: 300000 | K32: =J32-I32 -> 9000 | L32: 285714.29 | N32: 300000 | O32: 300000 | P32: 300000 | Q32: 300000 | R32: 300000 | S32: =VLOOKUP(B32,[2]Лист_1!$A$1:$C$65536,3,0) -> 300000 | T32: =I32*$T$1 -> 270630 | U32: 300000 | V32: =E32*$V$1 -> 291000 | W32: =VLOOKUP(B32,[3]Лист_1!$A$5:$F$55,4,0) -> 249600 | X32: =VLOOKUP(B32,[3]Лист_1!$A$5:$D$54,3,0) -> 12480 | Y32: =E32*$Y$1 -> 297000 | Z32: =VLOOKUP(B32,[6]Лист_1!$C$5:$E$64,3,0) -> 288800 | AB32: =E32*$AB$1 -> 333000 | AC32: =VLOOKUP(B32,[7]Лист_1!$A$3:$E$57,4,0) -> 300000 | AD32: =E32*$AD$1 -> 342000 | AE32: =VLOOKUP(B32,[4]Лист_1!$A$5:$D$59,3,0) -> 300000 | AF32: =E32*$AF$1 -> 351000 | AG32: =VLOOKUP(B32,[5]Лист_1!$A$3:$C$50,3,0) -> 300000 | AH32: =G32*$AF$1 -> 334285.71 | AI32: =VLOOKUP(B32,[29]Лист_1!$A$5:$C$67,3,0) -> 300000
A33: =A32+1 -> 28 | B33: КОНДИТЕРСКАЯ ФАБРИКА ПОБЕДА ООО | C33: Победа Вкуса | D33: 3 | E33: 114875 | F33: =E33*$F$1 -> 111428.75 | G33: =VLOOKUP(B33,[1]Лист_1!$A$1:$G$65536,7,0) -> 114875 | H33: =G33-F33 -> 3446.25 | I33: =E33*$I$1 -> 111428.75 | J33: 120619 | K33: =J33-I33 -> 9190.25 | L33: 114875 | N33: =E33*$N$1 -> 120618.75 | O33: 119030 | P33: =E33*$P$1 -> 124065 | Q33: 114875 | R33: =G33*$P$1 -> 124065 | S33: =VLOOKUP(B33,[2]Лист_1!$A$1:$C$65536,3,0) -> 139025 | T33: =I33*$T$1 -> 103628.74 | U33: 135455 | V33: =E33*$V$1 -> 111428.75 | W33: =VLOOKUP(B33,[3]Лист_1!$A$5:$F$55,4,0) -> 116436 | X33: =VLOOKUP(B33,[3]Лист_1!$A$5:$D$54,3,0) -> 5821.8 | Y33: =E33*$Y$1 -> 113726.25 | Z33: =VLOOKUP(B33,[6]Лист_1!$C$5:$E$64,3,0) -> 121647 | AB33: =E33*$AB$1 -> 127511.25 | AC33: 86175 | AD33: =E33*$AD$1 -> 130957.5 | AE33: =VLOOKUP(B33,[4]Лист_1!$A$5:$D$59,3,0) -> 139128 | AF33: =E33*$AF$1 -> 134403.75 | AG33: =VLOOKUP(B33,[5]Лист_1!$A$3:$C$50,3,0) -> 84140 | AH33: =G33*$AF$1 -> 134403.75 | AI33: =VLOOKUP(B33,[29]Лист_1!$A$5:$C$67,3,0) -> 108090
A34: =A33+1 -> 29 | B34: КРАСНАЯ ПОЛЯНА НАО | C34: Красная поляна | D34: 3 | E34: 94687 | F34: =E34*$F$1 -> 91846.39 | G34: =VLOOKUP(B34,[1]Лист_1!$A$1:$G$65536,7,0) -> 82998.038 | H34: =G34-F34 -> -8848.3519 | I34: =E34*$I$1 -> 91846.39 | J34: 100000 | K34: =J34-I34 -> 8153.61 | L34: 234952.44 | N34: =E34*$N$1 -> 99421.35 | O34: 112057.5 | P34: =E34*$P$1 -> 102261.96 | R34: =G34*$P$1 -> 89637.881 | S34: =VLOOKUP(B34,[2]Лист_1!$A$1:$C$65536,3,0) -> 286480.59 | T34: =I34*$T$1 -> 85417.143 | U34: 126472 | V34: =E34*$V$1 -> 91846.39 | W34: =VLOOKUP(B34,[3]Лист_1!$A$5:$F$55,4,0) -> 141601.02 | X34: =VLOOKUP(B34,[3]Лист_1!$A$5:$D$54,3,0) -> 7080.051 | Y34: =E34*$Y$1 -> 93740.13 | Z34: =VLOOKUP(B34,[6]Лист_1!$C$5:$E$64,3,0) -> 119417.2 | AB34: =E34*$AB$1 -> 105102.57 | AC34: =VLOOKUP(B34,[7]Лист_1!$A$3:$E$57,4,0) -> 123893 | AD34: =E34*$AD$1 -> 107943.18 | AE34: =VLOOKUP(B34,[4]Лист_1!$A$5:$D$59,3,0) -> 114042.62 | AF34: =E34*$AF$1 -> 110783.79 | AG34: =VLOOKUP(B34,[5]Лист_1!$A$3:$C$50,3,0) -> 119728.12 | AH34: =G34*$AF$1 -> 97107.705 | AI34: =VLOOKUP(B34,[29]Лист_1!$A$5:$C$67,3,0) -> 148190.2
A35: =A34+1 -> 30 | B35: Л'ОРЕАЛЬ АО | C35: CDMO | D35: 1 | E35: 57398 | F35: =E35*$F$1 -> 55676.06 | G35: =VLOOKUP(B35,[1]Лист_1!$A$1:$G$65536,7,0) -> 42565.333 | H35: =G35-F35 -> -13110.727 | I35: =E35*$I$1 -> 55676.06 | J35: 25246 | K35: =J35-I35 -> -30430.06 | L35: 42565.333 | N35: =E35*$N$1 -> 60267.9 | O35: 61086 | P35: =E35*$P$1 -> 61989.84 | Q35: 66610.1 | R35: =E35*$R$1 -> 57971.98 | S35: =VLOOKUP(B35,[2]Лист_1!$A$1:$C$65536,3,0) -> 18521.143 | T35: =I35*$T$1 -> 51778.736 | U35: 42566.143 | V35: =E35*$V$1 -> 55676.06 | W35: =VLOOKUP(B35,[3]Лист_1!$A$5:$F$55,4,0) -> 24044.19 | X35: =VLOOKUP(B35,[3]Лист_1!$A$5:$D$54,3,0) -> 1202.2095 | Y35: =E35*$Y$1 -> 56824.02 | AB35: =E35*$AB$1 -> 63711.78 | AC35: =VLOOKUP(B35,[7]Лист_1!$A$3:$E$57,4,0) -> 45139.267 | AD35: =E35*$AD$1 -> 65433.72 | AE35: =VLOOKUP(B35,[4]Лист_1!$A$5:$D$59,3,0) -> 117090.63 | AF35: =E35*$AF$1 -> 67155.66 | AG35: =VLOOKUP(B35,[5]Лист_1!$A$3:$C$50,3,0) -> 242472.96 | AH35: =G35*$AF$1 -> 49801.44 | AI35: =VLOOKUP(B35,[29]Лист_1!$A$5:$C$67,3,0) -> 119586.44
A36: =A35+1 -> 31 | B36: Майндбокс ООО | C36: Mindbox | D36: 3 | E36: 297190.23 | F36: =E36*$F$1 -> 288274.53 | G36: =VLOOKUP(B36,[1]Лист_1!$A$1:$G$65536,7,0) -> 111254.67 | H36: =G36-F36 -> -177019.86 | I36: =E36*$I$1 -> 288274.53 | J36: 100000 | K36: =J36-I36 -> -188274.53 | L36: 166070 | N36: =E36*$N$1 -> 312049.74
A37: =A36+1 -> 32 | B37: МАРС ООО | C37: Марс - комплексный проект, подписание доков, команда (Давтян, Ерёмин) | E37: 1616671.7 | F37: =E37*$F$1 -> 1568171.5 | G37: =VLOOKUP(B37,[1]Лист_1!$A$1:$G$65536,7,0)+499525 -> 1006325 | H37: =G37-F37 -> -561846.52 | I37: =E37*$I$1 -> 1568171.5 | K37: -208172 | N37: =E37*$N$1 -> 1697505.3 | P37: =E37*$P$1 -> 1746005.4 | R37: =E37*$R$1 -> 1632838.4 | T37: =I37*$T$1 -> 1458399.5 | V37: =E37*$V$1 -> 1568171.5 | Y37: =E37*$Y$1 -> 1600504.9 | AB37: =E37*$AB$1 -> 1794505.6 | AD37: =E37*$AD$1 -> 1843005.7 | AF37: =E37*$AF$1 -> 1891505.8 | AH37: =G37*$AF$1 -> 1177400.2
A38: =A37+1 -> 33 | B38: МАРС ООО | C38: Экосистема | D38: 5 | J38: 120000 | O38: 277050 | Q38: 82000 | R38: =E38*$R$1 -> 0 | S38: 1150600 | T38: =I38*$T$1 -> 0 | U38: 248500 | V38: =E38*$V$1 -> 0 | W38: =[3]Лист_1!$D$35 -> 160500 | X38: 8025 | Z38: 177050 | AC38: 158655 | AD38: =E38*$AD$1 -> 0 | AE38: 128350 | AG38: 215600 | AI38: 484280
A39: =A38+1 -> 34 | B39: РУСКАН АО | C39: Royal Canin | D39: 1 | J39: 500000 | L39: 571650 | O39: 606100 | Q39: 1155200 | R39: =E39*$R$1 -> 0 | S39: 762665 | T39: =I39*$T$1 -> 0 | U39: 562125 | V39: =E39*$V$1 -> 0 | W39: 534650 | Z39: 531200 | AC39: 701025 | AD39: =E39*$AD$1 -> 0 | AE39: =126000+826900 -> 952900 | AG39: 843475 | AI39: =VLOOKUP(B39,[29]Лист_1!$A$5:$C$67,3,0)+1200000 -> 2150970
A40: =A39+1 -> 35 | B40: =B37 -> МАРС ООО | C40: Kinpet | D40: 3 | J40: 540000 | L40: 563246.25 | O40: 638975 | Q40: 476189 | R40: =E40*$R$1 -> 0 | S40: 508975 | T40: =I40*$T$1 -> 0 | U40: 670351 | V40: =E40*$V$1 -> 0 | W40: 635002.5 | X40: 31750.17 | Z40: 454000 | AC40: 591550.07 | AD40: =E40*$AD$1 -> 0 | AE40: 554737.54 | AG40: 525887.54 | AI40: 492850
...

Sheet База расходы
I1: Текущий курс
G2: 1 | H2: 101 | I2: 104 | J2: 35.61
A3: Источник затрат | B3: Расшифровка услуги | C3: Наименование поставщика | D3: Юр. лицо поставщика | E3: Оплата мес. пропорционально году с конвертацией в руб. | F3: Оплата год/ конвертация в руб. | G3: Оплата, руб/мес | H3: Оплата, $/мес | I3: Оплата,€/мес | J3: Оплата, ₾/мес | K3: Итого | L3: ЯНВАРЬ | M3: ИТОГО ЯНВАРЬ | N3: ФЕВРАЛЬ | O3: ИТОГО ФЕВРАЛЬ | P3: МАРТ | Q3: ИТОГО МАРТ | R3: АПРЕЛЬ | S3: ИТОГО АПРЕЛЬ | T3: МАЙ | U3: ИТОГО МАЙ | V3: ИЮНЬ | W3: ИТОГО ИЮНЬ | X3: ИЮЛЬ | Y3: ИТОГО ИЮЛЬ | Z3: АВГУСТ | AA3: ИТОГО АВГУСТ | AB3: СЕНТЯБРЬ | AC3: ИТОГО СЕНТЯБРЬ | AD3: ОКТЯБРЬ | AE3: ИТОГО ОКТЯБРЬ | AF3: НОЯБРЬ | AG3: ИТОГО НОЯБРЬ | AH3: ДЕКАБРЬ | AI3: ИТОГО ДЕКАБРЬ
A4: ПО организационные офис | B4: для всех | C4: Яндекс | D4: ЯНДЕКС ООО | E4: =G4 -> 25000 | F4: =E4*12 -> 300000 | G4: 25000 | K4: =SUM(G4:G24) -> 240568.95 | L4: 23817.61 | M4: =SUM(L4:L24) -> 197214.95 | N4: =23232.97+2.69 -> 23235.66 | O4: =SUM(N4:N24) -> 281809.81 | P4: =24017.93+2.98 -> 24020.91 | Q4: =SUM(P4:P24) -> 299050.64 | R4: =24421.09+2.88 -> 24423.97 | S4: =SUM(R4:R24) -> 264785.72 | T4: 42226.23 | U4: =SUM(T4:T24) -> 157722.3 | V4: =40671.51+3.11 -> 40674.62 | W4: =SUM(V4:V24) -> 70543.94 | X4: 41336 | Y4: =SUM(X4:X24) -> 61345.82 | Z4: =42768+3.21 -> 42771.21 | AA4: =SUM(Z4:Z24) -> 142293.33 | AB4: 38978 | AC4: =SUM(AB4:AB24) -> 148400.12 | AD4: 40469.3 | AE4: =SUM(AD4:AD24) -> 109991.42 | AF4: =39665+3.11 -> 39668.11 | AG4: =SUM(AF4:AF24) -> 383672.56 | AH4: 39346.76 | AI4: =SUM(AH4:AH24) -> 228482.64
B5: для всех | C5: Планфикс | D5: ООО "Сфера" | E5: 80000 | F5: =E5*12 -> 960000 | G5: 80000 | L5: 75720 | N5: 75720 | P5: 75720 | R5: 75720 | T5: 75720 | V5: 9268.8
B6: для всех | D6: ООО "Цифровое облако" | X6: 5000 | Z6: 80000 | AB6: 50000 | AD6: 50000 | AF6: 53894.44 | AH6: 78582.93
B7: для всех | C7: Дискорд | D7: Дискорд | E7: =G7 -> 1008.99 | F7: =E7*12 -> 12107.88 | G7: =H7*H2 -> 1008.99 | H7: 9.99 | L7: 0 | N7: 968.13 | P7: 890.51 | R7: 0 | T7: 0 | V7: 0 | X7: 0 | Z7: 0 | AB7: 0 | AD7: 0 | AF7: 0 | AH7: 0
B8: для всех | C8: пинтест | D8: СКБ-СОФТ | AF8: 125000 | AH8: 0
B9: для всех | C9: EmailMaker | D9: БЛОЧНЫЙ РЕДАКТОР ООО | E9: =F9/12 -> 6800 | F9: 81600 | G9: =E9 -> 6800 | L9: 6800 | N9: 6800 | P9: 6800 | R9: 6800 | T9: 20400 | V9: 0 | X9: 0 | Z9: 6800 | AB9: 6800 | AD9: 6800 | AF9: 6800 | AH9: 6800
B10: онлайн-доска | C10: Miro | D10: Miro | E10: =G10 -> 3030 | F10: =E10*12 -> 36360 | G10: =H10*H2 -> 3030 | H10: 30 | L10: 1942.6 | N10: 3131.45 | P10: 906.73 | T10: 1594.2 | V10: 1.2 | X10: 1594.2 | Z10: 5617.8 | AB10: 5617.8 | AD10: 5617.8 | AF10: 4117.6 | AH10: 1639.8
B11: Нейросеть | C11: Chat GPT | D11: Chat GPT | E11: =G11 -> 2020 | F11: =E11*12 -> 24240 | G11: =H11*H2 -> 2020 | H11: 20 | L11: 1956.2 | N11: 1728.8 | P11: =1782.8+1644.83+1710 -> 5137.63 | R11: =1558.38 -> 1558.38 | T11: =1536.34 -> 1536.34 | V11: =1646.82+1646.82 -> 3293.64 | X11: 3282.09 | Z11: 3630.27 | AB11: 3630.27 | AD11: 3630.27 | AF11: 5414.44 | AH11: 5359.69
B12: нейросеть по созданию картинок | C12: Midjourney | D12: Midjourney | E12: =G12 -> 2424 | F12: =E12*12 -> 29088 | G12: =H12*H2 -> 2424 | H12: 24 | L12: 0 | N12: 0 | P12: 0 | R12: 0 | T12: 0 | V12: 1882.08 | X12: 1882.08 | Z12: 1882.08 | AB12: 1882.08 | AD12: 1882.08 | AF12: 1882.08 | AH12: 1882.08
B13: платформа д/проведения онлайн-встречь | C13: zoom д/Вани | D13: zoom | E13: =G13 -> 1786.69 | F13: =E13*12 -> 21440.28 | G13: =H13*H2 -> 1786.69 | H13: 17.69 | L13: 0 | N13: 0 | P13: 0 | R13: 0 | T13: 0 | V13: 1572.32 | X13: 0 | Z13: 1590.77 | AB13: 1590.77 | AD13: 1590.77 | AF13: =1682.2+926.49 -> 2608.69 | AH13: 1671.78
B14: база данных | C14: ноушн д/Вани | D14: Notion | E14: =G14 -> 1273.61 | F14: =E14*12 -> 15283.32 | G14: =H14*H2 -> 1273.61 | H14: 12.61 | L14: 0 | N14: 0 | P14: 0 | R14: 0 | T14: 0 | V14: 0 | X14: 0 | Z14: 0 | AB14: 0 | AD14: 0 | AF14: 0 | AH14: 0
B15: для всех | C15: GOOGLE | D15: GOOGLE | E15: =G15 -> 1008.99 | F15: =E15*12 -> 12107.88 | G15: =H15*H2 -> 1008.99 | H15: 9.99 | L15: =1023.11+970.33 -> 1993.44 | N15: 880.82 | P15: 841.06 | R15: 0 | T15: 796.3 | V15: 783.42 | X15: 782.52 | Z15: 0 | AB15: 0 | AD15: 0 | AF15: 812.49 | AH15: 798.5
B16: биллинг Лидплана | C16: Прайсплан | D16: ЭДМИН ООО | E16: =F16/12 -> 3216.6667 | F16: 38600 | G16: =E16 -> 3216.6667
C17: Майндбокс | L17: 1.2 | N17: 1.2 | P17: 1.2 | R17: 1.2 | T17: =1.2+500 -> 501.2 | V17: 1.2 | X17: 1.2 | Z17: 1.2 | AB17: 1.2 | AD17: 1.2 | AF17: 1.2 | AH17: 1.2
B18: Сертификат 1-С Битрикс | C18: Савкин Т.А. ИП | D18: Савкин Т.А. ИП | N18: =43128/12 -> 3594 | P18: 0 | R18: 0 | T18: 0 | V18: 0 | X18: 0 | Z18: 0 | AB18: 39900 | AD18: 0 | AF18: 134000 | AH18: 91580
B19: для Вани | D19: папдл нет/крафтдокс | T19: 948.03 | V19: 0 | X19: 0 | Z19: 0 | AB19: 0 | AD19: 0 | AF19: 0 | AH19: 0
C20: Битрикс | G20: 100000 | L20: 75000 | N20: 150459.75 | P20: 169740 | R20: 128965.5
D21: Центр развития экономики | R21: 14000
C22: прочие сервисы карта | AF22: 9473.51 | AH22: 819.9
B23: сервис Monk | D23: нал | N23: 1290 | P23: 992.6 | R23: 0 | T23: 0 | V23: 0 | X23: 0 | Z23: 0 | AB23: 0 | AD23: 0 | AF23: 0 | AH23: 0
B24: агрегатор мессенджеров | C24: chat2desk | D24: ИТ Проспект ООО | E24: =G24 -> 13000 | F24: =E24*12 -> 156000 | G24: 13000 | L24: 9983.9 | N24: 14000 | P24: 14000 | R24: 13316.67 | T24: 14000 | V24: 13066.66 | X24: 7467.73 | Z24: 0 | AB24: 0 | AD24: 0 | AF24: 0 | AH24: 0
A25: ПО организационные HR | B25: объявления на сайте | C25: Хэдхантер | D25: "Хэдхантер" ООО | E25: =G25 -> 20000 | F25: =E25*12 -> 240000 | G25: 20000 | K25: =SUM(G25:G32) -> 73313.983 | L25: =7198.52+1585 -> 8783.52 | M25: =SUM(L25:L32) -> 53182.73 | N25: 9796 | O25: =SUM(N25:N32) -> 53987.95 | P25: 10314 | Q25: =SUM(P25:P32) -> 54369.34 | R25: 44490 | S25: =SUM(R25:R32) -> 86956.67 | T25: =1585+5273+6912 -> 13770 | U25: =SUM(T25:T32) -> 56236.67 | V25: 11033 | W25: =SUM(V25:V32) -> 53499.67 | X25: 27086 | Y25: =SUM(X25:X32) -> 52852.67 | Z25: 21092 | AA25: =SUM(Z25:Z32) -> 275349.44 | AB25: 29176 | AC25: =SUM(AB25:AB32) -> 308433.44 | AD25: 22147 | AE25: =SUM(AD25:AD32) -> 51404.44 | AF25: 25712 | AG25: =SUM(AF25:AF32) -> 55089.39 | AH25: 13056 | AI25: =SUM(AH25:AH32) -> 42366.57
B26: конструктор сайтов | C26: Тильда | D26: ТИЛЬДА ПАБЛИШИНГ ООО | E26: =G26 -> 1000 | F26: =G26*12 -> 12000 | G26: 1000 | L26: 0 | N26: 0 | P26: 0 | R26: 0 | T26: 0 | V26: 0 | X26: 0 | Z26: 0 | AB26: 0 | AD26: 0 | AF26: 0 | AH26: 0
B27: сервис обратной связи | C27: Раиса | D27: ПРАВОВЕД.РУ ЛАБ ООО | E27: =G27 -> 16666.66 | F27: =E27*12 -> 199999.92 | G27: 16666.66 | L27: 16666.66 | N27: 16666.67 | P27: 16666.67 | R27: 16666.67 | T27: 16666.67 | V27: 16666.67 | X27: 16666.67 | Z27: 16666.67 | AB27: 16666.67 | AD27: 16666.67 | AF27: 16666.67 | AH27: 16666.67
B28: платформа автоматизации найма | C28: Хантфлоу | D28: ХАНФЛОУ ООО | E28: =G28 -> 9100 | F28: =E28*12 -> 109200 | G28: 9100 | L28: 9100 | N28: 9100 | P28: 9100 | R28: 9100 | T28: 9100 | V28: 9100 | X28: 9100 | Z28: 11000 | AB28: 11000 | AD28: 11000 | AF28: 11000 | AH28: 11000
B29: платформа д/обучения, база знаний | C29: Кампус | D29: ТЕОРИИ ОТ ПРАКТИКОВ ООО | E29: =G29 -> 16700 | F29: =E29*12 -> 200400 | G29: 16700 | L29: 16700 | N29: 16700 | P29: 16700 | R29: 16700 | T29: 16700 | V29: 16700
B30: аутсорс-поиск | D30: ИП Скворцова | Z30: 225000 | AB30: 250000 | AD30: 0 | AF30: 0 | AH30: 0
B31: тестирование | C31: ПИФ | D31: ЭКОПСИ ТЕКНОЛОДЖИС ООО | E31: =G31 -> 8333.3333 | F31: 100000 | G31: =F31/12 -> 8333.3333 | L31: 0 | N31: 0 | P31: 0 | R31: 0 | T31: 0 | V31: 0 | X31: 0 | Z31: 0 | AB31: 0 | AD31: 0 | AF31: 0 | AH31: 0
B32: платформа д/онлайнконференций | C32: Zoom (HR) | D32: Zoom (HR) | E32: =H32*H2 -> 1513.99 | F32: =E32*12 -> 18167.88 | G32: =E32 -> 1513.99 | H32: 14.99 | L32: 1932.55 | N32: 1725.28 | P32: 1588.67 | R32: 0 | T32: 0 | V32: 0 | X32: 0 | Z32: 1590.77 | AB32: 1590.77 | AD32: 1590.77 | AF32: 1710.72 | AH32: 1643.9
A33: Сервисы отдела продаж | B33: Лицензия АМО ЦРМ | C33: АМО ЦРМ | D33: Абрамов Михаил Владимирович ИП | E33: =G33 -> 7303.66 | F33: =E33*12 -> 87643.92 | G33: 7303.66 | K33: =SUM(G33:G41) -> 39437.683 | L33: 7303.66 | M33: =SUM(L33:L41) -> 12061.66 | N33: 7303.66 | O33: =SUM(N33:N41) -> 11288.94 | P33: 5994 | Q33: =SUM(P33:P41) -> 13414.97 | R33: 5994 | S33: =SUM(R33:R41) -> 13389.71 | T33: 5994 | U33: =SUM(T33:T41) -> 20127.48 | V33: 5994 | W33: =SUM(V33:V41) -> 48356.26 | X33: 5994 | Y33: =SUM(X33:X41) -> 10401.33 | Z33: 5994 | AA33: =SUM(Z33:Z41) -> 23299.64 | AB33: 5994 | AC33: =SUM(AB33:AB41) -> 10468.21 | AD33: 5994 | AE33: =SUM(AD33:AD41) -> 11370.08 | AF33: =20388/7 -> 2912.5714 | AG33: =SUM(AF33:AF41) -> 7579.0614 | AH33: =20388/7 -> 2912.5714 | AI33: =SUM(AH33:AH41) -> 7249.0114
B34: дополнение к АМО | C34: Почтовик | D34: Команда Ф5 ООО | E34: =G34 -> 1794 | F34: 21528 | G34: =F34/12 -> 1794 | L34: 0 | N34: 0 | P34: 0 | R34: 0 | T34: 0 | V34: 0 | X34: 0 | Z34: 0 | AB34: 0 | AD34: 0 | AF34: 0 | AH34: 0
B35: телефония | C35: Сипуини | D35: СИПУНИ РУС ООО | E35: =G35 -> 953.33333 | F35: 11440 | G35: =F35/12 -> 953.33333 | L35: 0 | N35: 0 | P35: 0 | R35: 0 | T35: 0 | V35: 0 | X35: 0 | Z35: 0 | AB35: 0 | AD35: 900
B36: телефония | C36: Сансим | D36: САНСИМ АО | E36: =G36 -> 1400 | F36: =E36*12 -> 16800 | G36: 1400 | L36: 1565.45 | N36: 1000 | P36: 1582.3 | R36: =587.99 -> 587.99 | T36: =642.26+1000+510+3.88+1200 -> 3356.14 | V36: 1529.94 | X36: 1576.81 | Z36: =1599.27 -> 1599.27 | AB36: 1623.44 | AD36: 1625.31 | AF36: 1798.81 | AH36: 1683.43
B37: тенд. площадка | C37: Тендеры и закупки | D37: Тендеры и закупки | E37: =G37 -> 1200 | F37: =E37*12 -> 14400 | G37: 1200 | L37: 1260 | N37: 1260 | P37: 1260 | R37: 1260 | T37: 1260 | V37: 1260 | X37: 1260 | Z37: 1260 | AB37: 1260 | AD37: 1260 | AF37: 1260 | AH37: 1260
B38: тендерные площадки | C38: Ростендер/Бидзаар | D38: тендерные площадки | E38: =G38 -> 25000 | F38: =E38*12 -> 300000 | G38: 25000 | L38: 0 | N38: 0 | P38: 2990 | R38: 0 | T38: 0 | V38: 0 | X38: 0 | Z38: 12855.6 | AB38: 0 | AD38: 0 | AF38: 0 | AH38: 0
D39: Савкин ИП | R39: 4000 | T39: 8000 | V39: 8000 | X39: 0 | Z39: 0 | AB39: 0 | AD39: 0 | AF39: 0 | AH39: 0
B40: конференции | D40: СОБЫТИЕ ООО | V40: 30000 | X40: 0 | Z40: 0 | AB40: 0 | AD40: 0 | AF40: 0 | AH40: 0
...

Sheet База расходы зп
V1: ПЛАН
G2: ПЛАН | O2: ФАКТ | V2: 2025
A3: РАСШИФРОВКА | B3: ПОДРАЗДЕЛЕНИЕ | C3: ДОЛЖНОСТЬ | D3: Штатных единиц | E3: Нижняя зарплатная вилка грейда | F3: Нижняя зарплатная вилка грейда | G3: Верхняя зарплатная вилка | H3: зпл с налогами с ФОТ за шт. ед. | I3: ФОТ с налогами | J3: ИТОГО | K3: произв/непроизв | L3: произв/непроизв % | M3: Штатных единиц | N3: зпл на руки за шт. ед. | O3: зпл на руки | P3: зпл с налогами с ФОТ за шт. ед. | Q3: зпл с налогами с ФОТ | R3: ФОТ с налогами | S3: ИТОГО | T3: произв/непроизв | U3: произв/непроизв % | V3: ИТОГО
A4: НЕПРОИЗВОДСТВЕННЫЕ СОТРУДНИКИ | B4: УПР | C4: Генерадьный директор | D4: 1 | G4: 870135 | H4: =G4/0.87+G4/0.87*7.8% -> 1078167.3 | I4: 1078167 | J4: 1078167 | K4: =J4+J7+J12+J13+J17+J20+J27 -> 3289155 | L4: =K4*L53/K53 -> 33.455272 | M4: 1 | N4: =O4/M4 -> 870135 | O4: 870135 | P4: =Q4/M4 -> 1078167 | Q4: 1078167 | R4: =SUM(Q4:Q6) -> 1078167 | S4: =SUM(R4:R6) -> 1078167 | T4: =S4+S7+S12+S13+S17+S20+J27 -> 3289155 | U4: =T4*U53/T53 -> 40.214598 | V4: =R4 -> 1078167
C5: Исполнительный директор | D5: 1 | M5: 1
C6: Финансовый директор | D6: 1 | M6: 1
B7: БУХГАЛТЕРИЯ | C7: Руководитель отдела бухгалтерского и налогового учета | D7: 1 | G7: 100000 | H7: =G7/0.87+G7/0.87*7.8% -> 123908.05 | I7: =D7*H7 -> 123908.05 | J7: =SUM(I7:I11) -> 434272.92 | M7: 1 | N7: =O7/M7 -> 100000 | O7: 100000 | P7: =Q7/M7 -> 123908.05 | Q7: =O7/0.87+O7/0.87*7.8% -> 123908.05 | R7: =SUM(Q7:Q11) -> 434272.92 | S7: =SUM(R7:R11) -> 434272.92 | V7: =S7 -> 434272.92
C8: Заместитель генерального директора по общим вопросам | D8: 1 | G8: 90480 | H8: =G8/0.87+G8/0.87*7.8% -> 112112 | I8: =D8*H8 -> 112112 | M8: 1 | N8: =O8/M8 -> 90480 | O8: 90480 | P8: =Q8/M8 -> 112112 | Q8: =O8/0.87+O8/0.87*7.8% -> 112112
C9: Бухгалтер по первичной документации | D9: 1 | G9: 60000 | H9: =G9/0.87+G9/0.87*7.8% -> 74344.828 | I9: =D9*H9 -> 74344.828 | M9: 1 | N9: =O9/M9 -> 60000 | O9: 60000 | P9: =Q9/M9 -> 74344.828 | Q9: =O9/0.87+O9/0.87*7.8% -> 74344.828
